Workbook

Sheet 00_LEIA-ME
B2: PARTIU! APRENDER E EMPREENDER — CRONOGRAMA PAULÍNIA (NÚCLEO 2) — V2
B3: Instituto da Criança · Sebrae · Petrobras — V2: revisão crítica da V1, com correções de automação, capacidade e condicionamento de recomendação
B5: O QUE MUDOU NESTA VERSÃO (V2)
B6: Esta é uma revisão crítica do arquivo V1, feita a pedido da coordenação. As principais correções: (1) esclarecimento honesto sobre o que é automatizado por fórmula e o que exige regenerar o arquivo; (2) separação entre "turmas ativas na semana" e "capacidade física por noite"; (3) a Oficina de Gestão passa a ter duas alternativas explícitas (B1 e B2), nenhuma delas confirmada; (4) o cenário recomendado deixou de ser tratado como aprovado; (5) marcos de validação de quórum e simulação de atraso; (6) Cursos Técnicos reclassificados como datas de simulação, não compromissos; (7) cálculo de capacidade da Consultoria Individual. Ver a aba 19_LOG_DE_ALTERACOES para a lista completa, item a item.
B11: MATRIZ DE AUTOMAÇÃO — O QUE MUDA SOZINHO E O QUE EXIGE REGENERAR O ARQUIVO
B12: Regra geral: este arquivo NÃO tem macro/script embutido. Fórmulas do Excel recalculam sozinhas; qualquer coisa que dependa do algoritmo de alocação de salas/datas (Python) só muda depois de rodar scripts/build_workbook.py e gerar um novo arquivo.
B13: Premissa (aba 01_PREMISSAS) | C13: Abas atualizadas automaticamente / Abas que exigem regenerar (script)
B14: Cenário recomendado (dropdown A/B/C/D) | C14: AUTOMÁTICO: 04_RESUMO_EXECUTIVO e 05_COMPARATIVO_CENARIOS recalculam o destaque e os marcos por fórmula (INDEX/MATCH). EXIGE REGERAR: 10, 11, 12-15, 17 (cronograma mestre, agenda e turma a turma continuam no cenário B até serem regeneradas).
B15: Datas de início/fim das Palestras (PS) | C15: EXIGE REGERAR script/build_workbook.py: todas as datas de PS, e por consequência as datas de DH/OG/CT/EAD/CI, são recalculadas pelo motor de datas em Python (não há fórmula de calendário de turmas no Excel).
B16: Carga horária do DH (20h x 22h) | C16: EXIGE REGERAR: muda a duração de cada turma de DH em model.py; nenhuma fórmula recalcula isso no Excel.
B17: Nº de salas / frequência do DH (cenários A-D) | C17: EXIGE REGERAR: o algoritmo de alocação de sala por lote está em Python (model.py), não em fórmula de planilha.
B18: Quantidade de turmas de OG / CT / variante B1 x B2 | C18: EXIGE REGERAR: schedules gerados em Python (build_og_schedule_b1_dedicado / _b2_compartilhado / build_ct_schedule).
B19: Parâmetros de capacidade da Consultoria Individual (nº consultores, horas/dia, dias/semana, atendimentos simultâneos) | C19: AUTOMÁTICO: células editáveis na aba 15_EAD_CONSULTORIAS calculam por FÓRMULA (sem precisar regenerar) as semanas necessárias e a data de conclusão estimada.
B20: Recesso institucional (datas) | C20: PARCIAL: o texto e os indicadores citam a data por referência de célula (fórmula) nas abas 00/01/04/17; mas o bloqueio desse período no cálculo de datas de turma (para não agendar encontro dentro do recesso) exige regerar o script.
B22: SCRIPT A EXECUTAR PARA REGERAR: python3 scripts/build_workbook.py (edite scripts/model.py para mudar uma premissa estrutural antes de rodar). Gera um novo .xlsx — não sobrescreve versões anteriores automaticamente.
B24: COMO CLASSIFICAMOS CADA INFORMAÇÃO
B25: Confirmada | C25: Valor igual em pelo menos 2 fontes independentes, sem contradição.
B26: Premissa provisória | C26: Valor usado para construir o cronograma na ausência de confirmação formal; pode mudar.
B27: Divergência entre documentos | C27: Os documentos-fonte trazem valores diferentes para o mesmo item; nenhum foi descartado.
B28: Informação pendente de validação | C28: Dado ausente, incompleto ou com placeholder (ex.: fornecedor "?").
B29: Decisão recomendada | C29: Recomendação da análise, com justificativa — não é um fato, é uma sugestão de encaminhamento.
B30: Condicionado à validação | C30: Datas/indicadores calculados a partir de premissas ainda não confirmadas (salas, quórum, fornecedor) — NÃO são compromisso oficial.
B32: COMO NAVEGAR
B33: 01_PREMISSAS | C33: Painel de premissas editáveis, agora com coluna indicando se a mudança é automática ou exige regeneração.
B34: 02_DIVERGENCIAS | C34: Tabela completa de conflitos entre os 4 documentos-fonte.
B35: 03_FLUXO_DA_TRILHA | C35: Mapa da trilha PS → DH → OG → CT → EAD → CI, com as regras quantitativas encontradas.
B36: 04_RESUMO_EXECUTIVO | C36: Visão de 1 página — recomendação condicionada, não uma aprovação.
B37: 05_COMPARATIVO_CENARIOS | C37: Painel comparativo dos 4 cenários, com os dois indicadores de capacidade separados.
B38: 06 a 09_CENARIO A-D | C38: Turma a turma de cada cenário + marcos de validação de quórum + simulação de atraso de 7 dias.
B39: 07_CENARIO_B | C39: Inclui a comparação das duas variantes de espaço para a OG (B1 x B2).
B40: 10_CRONOGRAMA_MESTRE | C40: Linha do tempo completa (cenário B, variante B1 de OG) — texto corrigido sobre o recesso.
B41: 11_AGENDA_POR_SALA | C41: Ocupação de salas — inclui as duas variantes de OG (B1/B2).
B42: 12_TURMAS_DH | C42: PS 01-30 e DH 01-15 detalhados.
B43: 13_OFICINAS_GESTAO | C43: Detalhamento das duas variantes de OG (B1/B2), nenhuma confirmada.
B44: 14_CURSOS_TECNICOS | C44: Todas as datas classificadas como "proposta para simulação", com quórum e responsável pela validação.
... B49: 19_LOG_DE_ALTERACOES | C49: Lista completa das correções feitas nesta V2, item a item, em resposta à revisão crítica.

Sheet 01_PREMISSAS
B2: PREMISSAS DO CRONOGRAMA — V2
B3: Células amarelas são editáveis. A coluna "Automação" diz, para CADA premissa, se a mudança recalcula sozinha ou exige rodar scripts/build_workbook.py. Ver matriz completa na aba 00_LEIA-ME.
B5: CENÁRIO RECOMENDADO PARA AS ABAS 04 E 05 (ligado por fórmula)
B6: Cenário recomendado (dropdown) | C6: B | D6: Alimenta por fórmula os destaques e marcos das abas 04_RESUMO_EXECUTIVO e 05_COMPARATIVO_CENARIOS. | E6: Confirmada | F6: Automático (fórmula)
B8: PALESTRAS DE SENSIBILIZAÇÃO (PS)
B9: Item | C9: Valor | D9: Observação / Classificação | E9: Status | F9: Automação
B10: Data de início | C10: 46245 | D10: Confirmado em 3 fontes | E10: Confirmada | F10: Exige regeneração (script)
B11: Data-alvo de término | C11: 46310 | D11: Confirmado em 3 fontes | E11: Confirmada | F11: Exige regeneração (script)
B12: Total de turmas (Paulínia) | C12: 30 | D12: Base operacional J3=30; PDF macro Núcleo 2 = 30 turmas | E12: Confirmada | F12: Exige regeneração (script)
B13: Frequência | C13: 3x/semana (Ter/Qua/Qui) | D13: Cadência dedutível da planilha "Possibilidades" | E13: Premissa provisória | F13: Exige regeneração (script)
B15: DESENVOLVIMENTO HUMANO (DH)
B16: Item | C16: Valor | D16: Observação / Classificação | E16: Status | F16: Automação
B17: Total de turmas (Paulínia) | C17: 15 | D17: Confirmado em 3 fontes | E17: Confirmada | F17: Exige regeneração (script)
B18: Carga horária total — OPÇÃO USADA NO MODELO | C18: 20h / 10 encontros | D18: Usada pela simulação de cenários e citada em reunião | E18: Premissa provisória | F18: Exige regeneração (script)
B19: Carga horária total — OPÇÃO ALTERNATIVA (documental) | C19: 22h / 11 encontros | D19: Planilha operacional e PDF macro | E19: Divergência entre documentos | F19: Exige regeneração (script)
B20: Mínimo/Máximo de participantes por turma | C20: 20 / 40 | D20: Planilha operacional H4/I4 | E20: Confirmada | F20: Exige regeneração (script)
B21: Regra de formação — OPÇÃO A | C21: 2 PS = 1 DH | D21: Fecha exatamente com 30 PS → 15 DH | E21: Premissa provisória | F21: Exige regeneração (script)
B22: Regra de formação — OPÇÃO B (anotação divergente) | C22: 4 OS = 1 DH | D22: "OS" não existe na trilha; provável erro de digitação. Não fecha com 15 turmas mesmo lendo como "PS" | E22: Divergência entre documentos | F22: —
B23: Frequência semanal a comparar | C23: 2x ou 5x por semana | D23: Cenários A-D | E23: Premissa provisória | F23: Exige regeneração (script)
B24: Nº de salas a comparar | C24: 2 ou 3 | D24: Cenários A-D | E24: Premissa provisória | F24: Exige regeneração (script)
B25: Gatilho para 1º curso técnico | C25: Após a 4ª turma de DH concluída | D25: Planilha operacional, anotação A34 | E25: Premissa provisória | F25: Exige regeneração (script)
B27: OFICINA DE GESTÃO (OG) — DUAS VARIANTES, NENHUMA CONFIRMADA
B28: Item | C28: Valor | D28: Observação / Classificação | E28: Status | F28: Automação
B29: Total de turmas — OPÇÃO USADA NO MODELO | C29: 15 | D29: Planilha operacional J5=15 (1 OG por turma de DH concluída) | E29: Premissa provisória | F29: Exige regeneração (script)
B30: Total de turmas — LEITURA ALTERNATIVA | C30: ≈7 a 8 | D30: Anotação "2 DH = 1 OG + 1 CT" (A28) aplicada literalmente | E30: Divergência entre documentos | F30: —
B31: Variante B1 — espaço | C31: 3 espaços ADICIONAIS, fora das 3 salas de DH | D31: NÃO CONFIRMADO. Ver comparação B1 x B2 na aba 07_CENARIO_B. | E31: Informação pendente de validação | F31: Exige regeneração (script)
B32: Variante B2 — espaço | C32: As mesmas 3 salas de DH (sem espaço adicional) | D32: OG só pode começar após o fim total da fase de DH (04/11) — ver aba 07. | E32: Decisão recomendada | F32: Exige regeneração (script)
B33: Carga horária / Encontros | C33: 4h / 2 encontros | D33: Planilha operacional F5/G5 | E33: Confirmada | F33: Exige regeneração (script)
B34: Mínimo/máximo de participantes | C34: 15 / 18 | D34: Planilha operacional H5/I5 | E34: Confirmada | F34: Exige regeneração (script)
B36: CURSOS TÉCNICOS (CT) — DATAS SÃO PROPOSTA PARA SIMULAÇÃO
B37: Item | C37: Valor | D37: Observação / Classificação | E37: Status | F37: Automação
B38: Total de turmas — OPÇÃO USADA NO MODELO | C38: 10 | D38: Soma de J6:J12 (7 temas) | E38: Premissa provisória | F38: Exige regeneração (script)
B39: Total de turmas — META CONTRATUAL (PDF macro) | C39: 13 | D39: PDF, Núcleo 2 = 13 turmas = 195 pessoas | E39: Divergência entre documentos | F39: —
B40: Diferença a validar | C40: 3 turmas | D40: Temas/fornecedores não definidos neste material | E40: Informação pendente de validação | F40: —
B41: Frequência / Turno | C41: 5x/semana, 4h/dia, noite | D41: Planilha operacional e briefing | E41: Confirmada | F41: Exige regeneração (script)
B42: Quórum mínimo por turma | C42: 14 a 18 (varia por curso/fornecedor) | D42: Planilha operacional H6:H12; reunião cita 16 como referência geral | E42: Divergência entre documentos | F42: —
B43: Classificação de TODAS as datas de CT nesta versão | C43: Proposta para simulação — pendente de quórum, contratação e validação do fornecedor | D43: Nenhuma data de CT é compromisso oficial (item 6 da revisão crítica) | E43: Condicionado à validação | F43: —
B45: CONSULTORIA INDIVIDUAL (CI) — CALCULADORA DE CAPACIDADE NA ABA 15
B46: Item | C46: Valor | D46: Observação / Classificação | E46: Status | F46: Automação
B47: Meta de pessoas / atendimentos por pessoa / horas por atendimento | C47: 150 / 3 / 1h | D47: Nota J14 (450 atend./3) e PDF macro ("13 turmas = 150 pessoas") | E47: Confirmada | F47: Exige regeneração (script)
...

Sheet 02_DIVERGENCIAS
B2: DIVERGÊNCIAS ENTRE OS 4 DOCUMENTOS — NADA FOI CORRIGIDO SILENCIOSAMENTE
B3: Toda linha aponta os documentos envolvidos, o impacto no cronograma e uma decisão provisória — a validar com Sebrae/Instituto
B5: Tema | C5: Divergência encontrada | D5: Documentos envolvidos | E5: Valores em conflito | F5: Impacto no cronograma | G5: Decisão recomendada (provisória) | H5: Classificação
B6: Carga horária do DH | C6: Planilha operacional e PDF contratual indicam 22h/11 encontros; reunião recente relata redução para 20h pelo Sebrae, sem documento formal. | D6: Proposta (xlsx) + PDF macro vs. ata de reunião / Simulação de cenários | E6: 22h / 11 encontros vs. 20h / 10 encontros | F6: Muito alto: cada turma de DH muda ±1 semana de duração; em 15 turmas encadeadas, o efeito acumulado desloca o início dos cursos técnicos e o fim da fase DH em várias semanas. | G6: Usar 20h/10 encontros apenas como premissa de trabalho (é o que consta na simulação mais recente), mas obter confirmação formal por escrito do Sebrae antes de compromissar datas com a Petrobras. | H6: Divergência entre documentos
B7: Quantidade de turmas de Curso Técnico | C7: O documento macro contratual (Anexos do projeto) indica 13 turmas para o Núcleo 2 (Paulínia); a planilha operacional detalhada soma apenas 10 turmas nos 7 temas listados. | D7: PDF "Apres. Projeto e Anexos 01.2026" vs. Proposta (xlsx) | E7: 13 turmas (meta contratual) vs. 10 turmas (planilha operacional) | F7: Muito alto: se 13 for a meta válida, faltam 3 turmas/fornecedores a contratar, o que desloca o fim da fase de cursos técnicos e a meta de 195 participantes. | G7: Levantar com a coordenação quais 3 turmas adicionais fariam sentido e formalizar com os fornecedores antes de assumir 13 como meta. TODAS as datas de CT nesta V2 são propostas para simulação — ver aba 14. | H7: Divergência entre documentos
B8: Regra de formação do DH a partir das Palestras | C8: A planilha operacional traz duas anotações conflitantes: "2 PS = 1 DH" (fecha com 15 turmas) e "4 OS = 1 DH" (não fecha; "OS" não corresponde a nenhuma sigla da trilha). | D8: Proposta (xlsx), observações A27 e A30 | E8: 2 PS = 1 DH vs. 4 OS = 1 DH | F8: Alto: define o ritmo de liberação de novos lotes de DH; usar a regra errada muda a data de abertura de cada turma. | G8: Adotar "2 PS = 1 DH" (única leitura que fecha com as 15 turmas confirmadas) e tratar "4 OS = 1 DH" como possível erro de digitação a confirmar. | H8: Divergência entre documentos
B9: Espaço físico para a Oficina de Gestão | C9: O cenário recomendado (B) usa 3 salas para o DH, mas essas 3 salas ficam ocupadas por lotes consecutivos durante toda a fase (sem vaga livre). A V1 deste arquivo assumiu 3 espaços ADICIONAIS sem confirmar isso — foi um erro de tratamento apontado na revisão crítica. | D9: Achado desta análise (nenhum dos 4 documentos originais cruzou a agenda de sala do DH com a da OG) | E9: B1: 3 salas de DH + 3 espaços adicionais (6 no total, NÃO confirmado) vs. B2: 3 salas compartilhadas (OG só após o fim total do DH, em 04/11) | F9: Muito alto: se B1 não for viabilizado, a OG só pode começar após 04/11 (variante B2), atrasando toda a cadeia até a Consultoria Individual em até ~2 semanas. | G9: Não tratar B1 como confirmado. Levar as duas alternativas (B1 x B2, comparadas na aba 07_CENARIO_B) à coordenação para decisão explícita sobre espaço físico antes de comunicar datas de OG. | H9: Divergência entre documentos
B10: Regra de composição da Oficina de Gestão e Curso Técnico | C10: A planilha operacional lista 15 turmas de OG (1 para cada DH), mas também traz a anotação "2 DH = 1 OG + 1 CT", que implicaria só ~7-8 turmas de OG para 15 DH. | D10: Proposta (xlsx), linha J5 vs. observação A28 | E10: 15 turmas de OG (1:1 com DH) vs. ~7-8 turmas de OG (1 a cada 2 DH) | F10: Muito alto: dobra ou reduz pela metade a necessidade de espaço/horário de OG, afetando toda a fase seguinte à DH. | G10: Confirmar com a coordenação se cada turma de DH forma sua própria OG (15 no total) ou se as turmas de DH são pareadas antes da OG (aprox. 7-8 no total). | H10: Divergência entre documentos
B11: Quórum mínimo dos cursos técnicos | C11: A planilha operacional traz mínimos de 14 ou 15 participantes por turma, variando por curso; a reunião menciona 16 como referência geral. | D11: Proposta (xlsx), coluna H vs. ata de reunião | E11: 14-15 (planilha, por curso) vs. 16 (reunião, geral) | F11: Alto: se 16 for o piso real exigido pelos fornecedores, pode faltar gente inscrita quando 4 turmas de DH (≈80 pessoas) alimentam 2 turmas técnicas. | G11: Confirmar o mínimo por fornecedor/curso antes de fechar contratos, em vez de aplicar um número único a todos os cursos. | H11: Divergência entre documentos
B12: Disponibilidade de salas para o DH | C12: O cronograma anterior da coordenação foi desenhado com 3 salas simultâneas; a discussão mais recente também cogita apenas 2 salas. | D12: "Possibilidades de Cronograma" (título da aba: "3 Salas Simultâneas") vs. briefing / Simulação de cenários | E12: 3 salas vs. 2 salas | F12: Muito alto: é a variável que mais muda a duração total da fase de DH. | G12: Confirmar com antecedência a disponibilidade real e exclusiva de salas à noite antes de comunicar datas ao Sebrae — ver comparativo de cenários na aba 05. | H12: Divergência entre documentos
B13: Recesso institucional | C13: A simulação de cenários bloqueia 21/12/2026 a 08/01/2027 como recesso, mas não há confirmação formal de que o Instituto/Sebrae adotarão esse recesso. | D13: Simulação de cenários (aba "Premissas e Pendências") | E13: 21/12/2026 a 08/01/2027 (assumido) vs. nenhuma confirmação | F13: Médio: cenários que já se estendem para dezembro/janeiro ficam ainda mais espremidos ou mais longos conforme o recesso seja confirmado ou não. | G13: Confirmar a duração exata do recesso institucional 2026/2027 junto à coordenação administrativa. | H13: Informação pendente de validação
B14: Datas com ano incorreto no cronograma anterior | C14: A aba "Paulínia" do arquivo "Possibilidades de Cronograma" tem uma seção rotulada "Janeiro de 2027" cujas datas de calendário estão grafadas como 2026, e ao menos uma linha traz data de término anterior à de início. | D14: "Possibilidades de Cronograma- Paulínia.xlsx", aba Paulínia | E14: Rótulo "Janeiro de 2027" com datas grafadas 2026; DHP9 com fim (18/11) anterior ao início (05/12) | F14: Alto: se usado sem correção, o leitor pode aceitar datas no ano errado ou uma janela invertida. | G14: Não usar essa planilha como fonte de datas finais; tratá-la apenas como registro histórico da tentativa anterior. | H14: Divergência entre documentos
B15: Fornecedor do curso de Jardinagem | C15: O cronograma anterior da coordenação registra o fornecedor do curso de Jardinagem como "?" — não definido. | D15: "Possibilidades de Cronograma- Paulínia.xlsx", célula R48 | E15: Fornecedor: "?" | F15: Alto: sem fornecedor confirmado, a turma de Jardinagem não pode ser efetivamente contratada nem ter data de início garantida. | G15: Priorizar a definição do fornecedor de Jardinagem antes de comunicar a data desta turma aos participantes. | H15: Informação pendente de validação
B16: Formação real de turma a partir das Palestras (quórum) | C16: O cronograma trata a formação de cada lote de DH como certa, mas nenhum documento confirma que toda Palestra realizada converte participantes suficientes em turma fechada. | D16: Nenhum dos 4 documentos discute risco de não-formação de turma | E16: Suposição implícita: 100% das Palestras geram quórum para o próximo lote de DH | F16: Alto: se um lote não atingir quórum, todo o restante da cadeia (a partir daquele lote) atrasa — ver simulação de atraso de 7 dias na aba 07_CENARIO_B. | G16: Adicionar marcos de validação de quórum antes de cada lote (aba 06-09) e tratar a formação de turma como "condicionada", não automática. | H16: Divergência entre documentos

Sheet 03_FLUXO_DA_TRILHA
B2: FLUXO DA TRILHA — PALESTRA → DH → OFICINA DE GESTÃO → CURSO TÉCNICO → EAD → CONSULTORIA
B3: Sequência obrigatória de dependências. Regras quantitativas mostradas como premissa/divergência, nunca como fato quando não confirmadas.
B5: PALESTRA DE SENSIBILIZAÇÃO (PS) | E5: DESENVOLVIMENTO HUMANO (DH) | H5: OFICINA DE GESTÃO (OG) | K5: CURSO TÉCNICO (CT) | N5: CURSO EAD | Q5: CONSULTORIA INDIVIDUAL (CI)
D6: → | G6: → | J6: → | M6: → | P6: →
B8: 30 turmas | E8: 15 turmas | H8: 15 turmas* (B1/B2) | K8: 10 turmas* (simulação) | N8: contínuo | Q8: meta 150 pessoas
B10: * Ver divergência quantitativa e status "condicionado à validação" nas abas 01, 02, 07 e 14.
B12: Relação quantitativa citada nos documentos | F12: Fecha com os totais confirmados (30 PS / 15 DH)? | J12: Classificação
B13: 30 PS → 15 DH (regra: 2 PS = 1 DH) | F13: Sim — 30 ÷ 2 = 15, bate exatamente com o total confirmado. Mas a formação de cada turma depende de quórum real — ver marcos de validação nas abas 06-09. | J13: Premissa provisória
B14: 30 PS → 15 DH (regra: 4 OS = 1 DH) | F14: Não — 30 ÷ 4 = 7,5, não bate com 15 turmas. Sigla "OS" também não existe na trilha. | J14: Divergência entre documentos
B15: 4 DH concluídos → 2 turmas de Curso Técnico (~80 pessoas formando 2 turmas de ~15-18) | F15: Aritmeticamente aproximado; indica que nem todos os 80 formandos migram para o mesmo curso técnico. Datas de CT são propostas para simulação, não compromisso — ver aba 14. | J15: Premissa provisória
B16: 2 DH = 1 OG + 1 CT | F16: Não fecha com as 15 turmas de OG citadas na planilha operacional (implicaria ~7-8 OG, não 15). | J16: Divergência entre documentos
B17: 15 DH → 15 OG (1 para 1) | F17: Consistente com o total de 15 turmas de OG, mas contradiz a regra "2 DH = 1 OG + 1 CT". Depende ainda de qual variante de espaço (B1 ou B2) for adotada. | J17: Premissa provisória
B19: LEGENDA DE ETAPAS
C20: PS - Palestra de Sensibilização
C21: DH - Desenvolvimento Humano
C22: OG - Oficina de Gestão
C23: CT - Curso Técnico
C24: EAD - Curso Online
C25: CI - Consultoria Individual
C26: Recesso / feriado

Sheet 04_RESUMO_EXECUTIVO
B2: PARTIU! APRENDER E EMPREENDER — PAULÍNIA (V2)
B3: Trilha completa: Palestra de Sensibilização → Desenvolvimento Humano → Oficina de Gestão → Curso Técnico → EAD → Consultoria Individual
B5: PERÍODO TOTAL: 11/08/2026 até parte de 2027 (ver observação abaixo) — cenário definido em 01_PREMISSAS ("Cenário recomendado")
B7: Início das Palestras | C7: Início do DH (cenário sel.) | D7: 4ª turma de DH concluída | E7: Fim do DH (cenário sel.) | F7: 1º Curso Técnico (proposta p/ simulação)
B8: =DATE(2026,8,11) | C8: =INDEX('05_COMPARATIVO_CENARIOS'!$H$6:$H$9,MATCH('01_PREMISSAS'!C6,'05_COMPARATIVO_CENARIOS'!$B$6:$B$9,0)) | D8: =INDEX('05_COMPARATIVO_CENARIOS'!$I$6:$I$9,MATCH('01_PREMISSAS'!C6,'05_COMPARATIVO_CENARIOS'!$B$6:$B$9,0)) | E8: =INDEX('05_COMPARATIVO_CENARIOS'!$J$6:$J$9,MATCH('01_PREMISSAS'!C6,'05_COMPARATIVO_CENARIOS'!$B$6:$B$9,0)) | F8: 46293
B10: Os 4 primeiros marcos recalculam por fórmula conforme o "Cenário recomendado" escolhido em 01_PREMISSAS. O marco de Curso Técnico segue fixo no Cenário B nesta versão (a grade completa de CT/OG/EAD/CI exige regeneração do arquivo para outro cenário — ver matriz em 00_LEIA-ME).
B12: LINHA DO TEMPO — CENÁRIO B (referência desta versão)
B13: Etapa | C13: AUG/26 | D13: SEP/26 | E13: OCT/26 | F13: NOV/26 | G13: DEC/26 | H13: JAN/27 | I13: FEB/27
B14: Palestras de Sensibilização
B15: Desenvolvimento Humano
B16: Oficina de Gestão (B1, não confirmada)
B17: Cursos Técnicos (proposta p/ simulação)
B18: Curso EAD
B19: Consultoria Individual (estimado)
B20: Recesso / feriados
B22: RECOMENDAÇÃO CONDICIONADA (NÃO É UMA APROVAÇÃO): Cenário B — 3 salas, DH 5x/semana. Menor duração — recomendado para negociação, condicionado à validação de salas, facilitadores, adesão dos participantes e espaços para a Oficina de Gestão (variantes B1 x B2, ver aba 07_CENARIO_B). O cenário B conclui o Desenvolvimento Humano antes do recesso e antecipa o início das etapas seguintes. Parte dos cursos técnicos e das consultorias permanece programada para 2027.
B27: LEGENDA
C28: Palestras de Sensibilização | E28: Desenvolvimento Humano | G28: Oficina de Gestão (B1, não confirmada) | I28: Cursos Técnicos (proposta p/ simulação) | K28: Curso EAD | M28: Consultoria Individual (estimado) | O28: Recesso/feriado
B30: Datas construídas a partir de premissas explicitadas nas abas 01, 02 e 03 — sujeitas a confirmação formal do Sebrae/Instituto. Nenhuma data de Curso Técnico ou Oficina de Gestão nesta versão é compromisso oficial.

Sheet 05_COMPARATIVO_CENARIOS
O1: ='01_PREMISSAS'!C6
B2: COMPARATIVO DOS 4 CENÁRIOS DE DESENVOLVIMENTO HUMANO (DH)
B3: Salas x Frequência semanal — indicadores recalculados por fórmula a partir das abas 06 a 09. O destaque de "cenário recomendado" segue a célula editável em 01_PREMISSAS.
C5: Cenário | D5: Salas | E5: Frequência DH | F5: Turmas ativas na semana (pico) | G5: Máx. turmas mesma noite | H5: Início do DH | I5: 4ª turma concluída | J5: 15ª turma concluída | K5: Duração (dias) | L5: Riscos principais | M5: Vantagens / Desvantagens | N5: Viabilidade (condicionada)
B6: A | C6: Cenário A | D6: 3 | E6: 2x/semana | F6: 6 | G6: 3 | H6: ='06_CENARIO_A'!C23 | I6: ='06_CENARIO_A'!C24 | J6: ='06_CENARIO_A'!C25 | K6: ='06_CENARIO_A'!C26 | L6: Sobreposição de turmas exige interleaving de dias (Seg/Qua com Ter/Qui) na mesma sala; termina em dezembro, próximo ao recesso. | M6: Vantagem: usa a capacidade máxima das 3 salas. Desvantagem: ritmo mais lento (2x/semana) atrasa toda a cadeia OG→CT→EAD→CI. | N6: Viável — condicionado à validação de salas e facilitadores.
B7: B | C7: Cenário B | D7: 3 | E7: 5x/semana | F7: 6 | G7: 3 | H7: ='07_CENARIO_B'!C23 | I7: ='07_CENARIO_B'!C24 | J7: ='07_CENARIO_B'!C25 | K7: ='07_CENARIO_B'!C26 | L7: Ritmo intenso (5x/semana) exige disponibilidade constante de facilitadores e das 3 salas em sequência apertada entre lotes; praticamente sem folga para atraso (ver simulação de 7 dias na aba 07). Espaço para a Oficina de Gestão ainda não definido entre as variantes B1/B2. | M7: Vantagem: conclui a fase DH mais cedo (04/11), abrindo mais espaço para OG, CT, EAD e CI ainda em 2026. Desvantagem: menor margem de faltas/reposição por turma; parte dos Cursos Técnicos e da Consultoria Individual permanece programada para 2027 mesmo neste cenário. | N7: Menor duração — recomendado para negociação, condicionado à validação de salas, facilitadores, adesão dos participantes e espaços para OG (ver B1 x B2 na aba 07).
B8: C | C8: Cenário C | D8: 2 | E8: 2x/semana | F8: 5 | G8: 2 | H8: ='08_CENARIO_C'!C23 | I8: ='08_CENARIO_C'!C24 | J8: ='08_CENARIO_C'!C25 | K8: ='08_CENARIO_C'!C26 | L8: Fase DH ultrapassa o recesso institucional e só termina em fevereiro/2027 — compromete seriamente o início dos cursos técnicos e a meta anual. | M8: Vantagem: nenhuma relevante frente aos demais cenários. Desvantagem: menor capacidade (2 salas) e maior duração total (169 dias). | N8: Não recomendado — atravessa o recesso e estende a fase DH até fevereiro/2027.
B9: D | C9: Cenário D | D9: 2 | E9: 5x/semana | F9: 4 | G9: 2 | H9: ='09_CENARIO_D'!C23 | I9: ='09_CENARIO_D'!C24 | J9: ='09_CENARIO_D'!C25 | K9: ='09_CENARIO_D'!C26 | L9: Alta intensidade diária (5x/semana) combinada a apenas 2 salas deixa pouquíssima folga para reposição de encontros perdidos. | M9: Vantagem: mais rápido que os cenários de 2x/semana. Desvantagem: capacidade mínima (2 salas) entre os 4 cenários. | N9: Viável com ressalvas — condicionado à validação de salas, facilitadores e folga mínima entre lotes.
B11: LEITURA: o cenário destacado em verde segue a célula "Cenário recomendado" em 01_PREMISSAS (troque A/B/C/D lá para recalcular o destaque aqui e em 04). Padrão atual: Cenário B — menor duração da fase DH (73 dias) entre os 4 cenários avaliados. Isso NÃO significa que o cenário está aprovado: a recomendação é condicionada à validação de salas, facilitadores, adesão dos participantes às Palestras/DH e definição do espaço para a Oficina de Gestão (B1 x B2, aba 07).

Sheet 06_CENARIO_A
B2: CENÁRIO A — 3 SALAS | DH 2x/semana
B3: Viavel, mas com maior sobreposicao e termino em dezembro. | Indicação: Alternativa equilibrada
B5: Turma DH | C5: Lote | D5: Sala | E5: Cadência | F5: Início | G5: Término | H5: Encontros | I5: Nº aprox. de participantes | J5: Observação
B6: DH 1 | C6: 1 | D6: Sala 1 | E6: Ter/Qui | F6: 46259 | G6: 46289 | H6: 10 | I6: —
B7: DH 2 | C7: 1 | D7: Sala 2 | E7: Ter/Qui | F7: 46259 | G7: 46289 | H7: 10 | I7: —
B8: DH 3 | C8: 1 | D8: Sala 3 | E8: Ter/Qui | F8: 46259 | G8: 46289 | H8: 10 | I8: —
B9: DH 4 | C9: 2 | D9: Sala 1 | E9: Seg/Qua | F9: 46274 | G9: 46309 | H9: 10 | I9: Encontro cai em feriado: 12/10
B10: DH 5 | C10: 2 | D10: Sala 2 | E10: Seg/Qua | F10: 46274 | G10: 46309 | H10: 10 | I10: Encontro cai em feriado: 12/10
B11: DH 6 | C11: 2 | D11: Sala 3 | E11: Seg/Qua | F11: 46274 | G11: 46309 | H11: 10 | I11: Encontro cai em feriado: 12/10
B12: DH 7 | C12: 3 | D12: Sala 1 | E12: Ter/Qui | F12: 46294 | G12: 46324 | H12: 10 | I12: —
B13: DH 8 | C13: 3 | D13: Sala 2 | E13: Ter/Qui | F13: 46294 | G13: 46324 | H13: 10 | I13: —
B14: DH 9 | C14: 3 | D14: Sala 3 | E14: Ter/Qui | F14: 46294 | G14: 46324 | H14: 10 | I14: —
B15: DH 10 | C15: 4 | D15: Sala 1 | E15: Seg/Qua | F15: 46314 | G15: 46349 | H15: 10 | I15: Encontro cai em feriado: 02/11
B16: DH 11 | C16: 4 | D16: Sala 2 | E16: Seg/Qua | F16: 46314 | G16: 46349 | H16: 10 | I16: Encontro cai em feriado: 02/11
B17: DH 12 | C17: 4 | D17: Sala 3 | E17: Seg/Qua | F17: 46314 | G17: 46349 | H17: 10 | I17: Encontro cai em feriado: 02/11
... B20: DH 15 | C20: 5 | D20: Sala 3 | E20: Ter/Qui | F20: 46329 | G20: 46359 | H20: 10 | I20: —
B22: Indicador | C22: Resultado | D22: Leitura
B23: Início da 1ª turma | C23: =MIN(F6:F20) | D23: Marco de início da fase de Desenvolvimento Humano
B24: Conclusão da 4ª turma | C24: =SMALL(G6:G20,4) | D24: Marco para liberar o primeiro lote de Curso Técnico (premissa: após 4 DH) — data PROPOSTA, condicionada a quórum real
B25: Conclusão da 15ª turma (todas) | C25: =MAX(G6:G20) | D25: Fim estimado da fase de Desenvolvimento Humano
B26: Duração da fase DH (dias corridos) | C26: =C25-C23+1 | D26: Da 1ª turma iniciada até a 15ª concluída
B27: Turmas ativas na mesma semana (pico) | C27: 6 | D27: Nº de turmas com o período [início,término] tocando a mesma semana corrida — NÃO é o nº de turmas se encontrando na mesma noite.
B28: Máximo de turmas na MESMA noite (mesma sala/horário) | C28: 3 | D28: Limite físico real: 3 sala(s) → no máximo 3 atividades simultâneas por noite. O uso alternado de dias (ex.: Seg/Qua com Ter/Qui) permite mais turmas ATIVAS na semana, mas não aumenta o nº de salas físicas disponíveis por noite.
B30: MARCOS DE VALIDAÇÃO DE QUÓRUM POR LOTE — formação de turma é CONDICIONADA, não automática
B31: Lote | C31: Data planejada de validação | D31: Data-limite / janela de contingência | E31: Impacto de atraso de 7 dias no lote | F31: Risco de palestra reagendada | G31: Status
B32: Lote 1 (DH 1, DH 2, DH 3) | C32: 46252 | D32: -15 dia(s) de folga antes de empurrar o lote 2 | E32: 4ª turma: +22d; fim da fase DH: +67d (considerando a folga natural entre lotes) | F32: Palestras deste lote podem precisar de reforço de mobilização/reagendamento se o quórum não fechar. | G32: Condicionado à validação
B33: Lote 2 (DH 4, DH 5, DH 6) | C33: 46267 | D33: -15 dia(s) de folga antes de empurrar o lote 3 | E33: 4ª turma: +7d; fim da fase DH: +52d (considerando a folga natural entre lotes) | F33: Palestras deste lote podem precisar de reforço de mobilização/reagendamento se o quórum não fechar. | G33: Condicionado à validação
B34: Lote 3 (DH 7, DH 8, DH 9) | C34: 46287 | D34: -10 dia(s) de folga antes de empurrar o lote 4 | E34: 4ª turma: sem mudança; fim da fase DH: +37d (considerando a folga natural entre lotes) | F34: Palestras deste lote podem precisar de reforço de mobilização/reagendamento se o quórum não fechar. | G34: Condicionado à validação
B35: Lote 4 (DH 10, DH 11, DH 12) | C35: 46307 | D35: -20 dia(s) de folga antes de empurrar o lote 5 | E35: 4ª turma: sem mudança; fim da fase DH: +27d (considerando a folga natural entre lotes) | F35: Palestras deste lote podem precisar de reforço de mobilização/reagendamento se o quórum não fechar. | G35: Condicionado à validação
B36: Lote 5 (DH 13, DH 14, DH 15) | C36: 46322 | D36: Último lote — atraso aqui só afeta o fim da fase DH | E36: 4ª turma: sem mudança; fim da fase DH: +7d (considerando a folga natural entre lotes) | F36: Palestras deste lote podem precisar de reforço de mobilização/reagendamento se o quórum não fechar. | G36: Condicionado à validação
B38: SIMULAÇÃO DE IMPACTO — ATRASO DE 7 DIAS NO LOTE 1 (ex.: quórum insuficiente nas primeiras Palestras)
B39: Cenário de folga | C39: 4ª turma concluída (original) | D39: 4ª turma concluída (com atraso) | E39: Fim da fase DH (original) | F39: Fim da fase DH (com atraso) | G39: Leitura
B40: Otimista — folgas naturais entre lotes absorvem parte do atraso | C40: 46309 | D40: 46331 | E40: 46359 | F40: 46426 | G40: 4ª turma desloca 22d; fim da fase DH desloca 67d
B41: Conservador (pior caso) — nenhuma folga é aproveitada, atraso se propaga integralmente | C41: 46309 | D41: 46316 | E41: 46359 | F41: 46366 | G41: 4ª turma desloca 7d; fim da fase DH desloca 7d

Sheet 07_CENARIO_B
B2: CENÁRIO B — 3 SALAS | DH 5x/semana ★ MENOR DURAÇÃO — RECOMENDADO PARA NEGOCIAÇÃO (condicionado)
B3: Maior velocidade; acompanha melhor a formacao das turmas. | Indicação: Recomendado para negociacao
B5: Turma DH | C5: Lote | D5: Sala | E5: Cadência | F5: Início | G5: Término | H5: Encontros | I5: Nº aprox. de participantes | J5: Observação
B6: DH 1 | C6: 1 | D6: Sala 1 | E6: Seg-Sex | F6: 46258 | G6: 46269 | H6: 10 | I6: —
B7: DH 2 | C7: 1 | D7: Sala 2 | E7: Seg-Sex | F7: 46258 | G7: 46269 | H7: 10 | I7: —
B8: DH 3 | C8: 1 | D8: Sala 3 | E8: Seg-Sex | F8: 46258 | G8: 46269 | H8: 10 | I8: —
B9: DH 4 | C9: 2 | D9: Sala 1 | E9: Seg-Sex | F9: 46273 | G9: 46286 | H9: 10 | I9: —
B10: DH 5 | C10: 2 | D10: Sala 2 | E10: Seg-Sex | F10: 46273 | G10: 46286 | H10: 10 | I10: —
B11: DH 6 | C11: 2 | D11: Sala 3 | E11: Seg-Sex | F11: 46273 | G11: 46286 | H11: 10 | I11: —
B12: DH 7 | C12: 3 | D12: Sala 1 | E12: Seg-Sex | F12: 46287 | G12: 46300 | H12: 10 | I12: —
B13: DH 8 | C13: 3 | D13: Sala 2 | E13: Seg-Sex | F13: 46287 | G13: 46300 | H13: 10 | I13: —
B14: DH 9 | C14: 3 | D14: Sala 3 | E14: Seg-Sex | F14: 46287 | G14: 46300 | H14: 10 | I14: —
B15: DH 10 | C15: 4 | D15: Sala 1 | E15: Seg-Sex | F15: 46301 | G15: 46315 | H15: 10 | I15: Encontro cai em feriado: 12/10
B16: DH 11 | C16: 4 | D16: Sala 2 | E16: Seg-Sex | F16: 46301 | G16: 46315 | H16: 10 | I16: Encontro cai em feriado: 12/10
B17: DH 12 | C17: 4 | D17: Sala 3 | E17: Seg-Sex | F17: 46301 | G17: 46315 | H17: 10 | I17: Encontro cai em feriado: 12/10
... B20: DH 15 | C20: 5 | D20: Sala 3 | E20: Seg-Sex | F20: 46316 | G20: 46330 | H20: 10 | I20: Encontro cai em feriado: 02/11
B22: Indicador | C22: Resultado | D22: Leitura
B23: Início da 1ª turma | C23: =MIN(F6:F20) | D23: Marco de início da fase de Desenvolvimento Humano
B24: Conclusão da 4ª turma | C24: =SMALL(G6:G20,4) | D24: Marco para liberar o primeiro lote de Curso Técnico (premissa: após 4 DH) — data PROPOSTA, condicionada a quórum real
B25: Conclusão da 15ª turma (todas) | C25: =MAX(G6:G20) | D25: Fim estimado da fase de Desenvolvimento Humano
B26: Duração da fase DH (dias corridos) | C26: =C25-C23+1 | D26: Da 1ª turma iniciada até a 15ª concluída
B27: Turmas ativas na mesma semana (pico) | C27: 6 | D27: Nº de turmas com o período [início,término] tocando a mesma semana corrida — NÃO é o nº de turmas se encontrando na mesma noite.
B28: Máximo de turmas na MESMA noite (mesma sala/horário) | C28: 3 | D28: Limite físico real: 3 sala(s) → no máximo 3 atividades simultâneas por noite. O uso alternado de dias (ex.: Seg/Qua com Ter/Qui) permite mais turmas ATIVAS na semana, mas não aumenta o nº de salas físicas disponíveis por noite.
B30: MARCOS DE VALIDAÇÃO DE QUÓRUM POR LOTE — formação de turma é CONDICIONADA, não automática
B31: Lote | C31: Data planejada de validação | D31: Data-limite / janela de contingência | E31: Impacto de atraso de 7 dias no lote | F31: Risco de palestra reagendada | G31: Status
B32: Lote 1 (DH 1, DH 2, DH 3) | C32: 46251 | D32: 4 dia(s) de folga antes de empurrar o lote 2 | E32: 4ª turma: +3d; fim da fase DH: sem mudança (considerando a folga natural entre lotes) | F32: Palestras deste lote podem precisar de reforço de mobilização/reagendamento se o quórum não fechar. | G32: Condicionado à validação
B33: Lote 2 (DH 4, DH 5, DH 6) | C33: 46266 | D33: 1 dia(s) de folga antes de empurrar o lote 3 | E33: 4ª turma: +7d; fim da fase DH: +4d (considerando a folga natural entre lotes) | F33: Palestras deste lote podem precisar de reforço de mobilização/reagendamento se o quórum não fechar. | G33: Condicionado à validação
B34: Lote 3 (DH 7, DH 8, DH 9) | C34: 46280 | D34: 1 dia(s) de folga antes de empurrar o lote 4 | E34: 4ª turma: sem mudança; fim da fase DH: +5d (considerando a folga natural entre lotes) | F34: Palestras deste lote podem precisar de reforço de mobilização/reagendamento se o quórum não fechar. | G34: Condicionado à validação
B35: Lote 4 (DH 10, DH 11, DH 12) | C35: 46294 | D35: 1 dia(s) de folga antes de empurrar o lote 5 | E35: 4ª turma: sem mudança; fim da fase DH: +6d (considerando a folga natural entre lotes) | F35: Palestras deste lote podem precisar de reforço de mobilização/reagendamento se o quórum não fechar. | G35: Condicionado à validação
B36: Lote 5 (DH 13, DH 14, DH 15) | C36: 46309 | D36: Último lote — atraso aqui só afeta o fim da fase DH | E36: 4ª turma: sem mudança; fim da fase DH: +7d (considerando a folga natural entre lotes) | F36: Palestras deste lote podem precisar de reforço de mobilização/reagendamento se o quórum não fechar. | G36: Condicionado à validação
B38: SIMULAÇÃO DE IMPACTO — ATRASO DE 7 DIAS NO LOTE 1 (ex.: quórum insuficiente nas primeiras Palestras)
B39: Cenário de folga | C39: 4ª turma concluída (original) | D39: 4ª turma concluída (com atraso) | E39: Fim da fase DH (original) | F39: Fim da fase DH (com atraso) | G39: Leitura
B40: Otimista — folgas naturais entre lotes absorvem parte do atraso | C40: 46286 | D40: 46289 | E40: 46330 | F40: 46330 | G40: 4ª turma desloca 3d; fim da fase DH desloca 0d
B41: Conservador (pior caso) — nenhuma folga é aproveitada, atraso se propaga integralmente | C41: 46286 | D41: 46293 | E41: 46330 | F41: 46337 | G41: 4ª turma desloca 7d; fim da fase DH desloca 7d
B43: OFICINA DE GESTÃO — DUAS VARIANTES DE ESPAÇO (NENHUMA CONFIRMADA) — "CENÁRIO B" NÃO DEFINE ISSO SOZINHO
B44: A V1 deste arquivo tratou 3 espaços adicionais de OG como certos. Nesta V2, isso é explicitado como uma escolha em aberto entre duas variantes — o nome do cenário muda conforme a escolha, porque a necessidade total de espaços físicos é diferente em cada uma.
B45: Variante | C45: Espaço usado | D45: OG início | E45: OG término | F45: Conflitos de sala | G45: Necessidade total de espaços | H45: Risco operacional
B46: Cenário B1 — 3 salas de DH + 3 espaços ADICIONAIS de OG | C46: 3 espaços dedicados, distintos das 3 salas de DH (NÃO CONFIRMADO) | D46: 46276 | E46: 46338 | F46: Nenhum (espaços dedicados, verificado dia a dia) | G46: 6 espaços no total (3 DH + 3 OG) | H46: Depende de viabilizar 3 espaços adicionais — sem eles, este plano não é executável.
B47: Cenário B2 — 3 salas totais, compartilhadas entre DH e OG | C47: As mesmas 3 salas do DH (sem espaço adicional) | D47: 46331 | E47: 46344 | F47: Nenhum (OG só ocupa a sala após o fim total da fase DH, em ondas sequenciais) | G47: 3 espaços no total (sem espaço adicional) | H47: OG só começa em 05/11/2026 (após o fim da fase DH) e só termina em 18/11/2026 — atraso de 55 dias no início da OG frente à variante B1, empurrando também Curso Técnico e Consultoria Individual para quem depende da OG.
B49: DECISÃO NECESSÁRIA: a coordenação precisa optar formalmente entre B1 (mais rápido, mas depende de 3 espaços adicionais não confirmados) e B2 (não depende de espaço extra, mas atrasa a OG e tudo que depende dela). Nenhuma das duas está aprovada nesta versão.

Sheet 08_CENARIO_C
B2: CENÁRIO C — 2 SALAS | DH 2x/semana
B3: Baixa capacidade; atravessa o recesso e termina em fevereiro. | Indicação: Nao recomendado
B5: Turma DH | C5: Lote | D5: Sala | E5: Cadência | F5: Início | G5: Término | H5: Encontros | I5: Nº aprox. de participantes | J5: Observação
B6: DH 1 | C6: 1 | D6: Sala 1 | E6: Ter/Qui | F6: 46259 | G6: 46289 | H6: 10 | I6: —
B7: DH 2 | C7: 1 | D7: Sala 2 | E7: Ter/Qui | F7: 46259 | G7: 46289 | H7: 10 | I7: —
B8: DH 3 | C8: 1 | D8: Sala 1 | E8: Seg/Qua | F8: 46258 | G8: 46293 | H8: 10 | I8: Encontro cai em feriado: 07/09
B9: DH 4 | C9: 2 | D9: Sala 2 | E9: Seg/Qua | F9: 46274 | G9: 46309 | H9: 10 | I9: Encontro cai em feriado: 12/10
B10: DH 5 | C10: 2 | D10: Sala 1 | E10: Ter/Qui | F10: 46294 | G10: 46324 | H10: 10 | I10: —
B11: DH 6 | C11: 2 | D11: Sala 2 | E11: Ter/Qui | F11: 46294 | G11: 46324 | H11: 10 | I11: —
B12: DH 7 | C12: 3 | D12: Sala 1 | E12: Seg/Qua | F12: 46295 | G12: 46335 | H12: 10 | I12: Encontro cai em feriado: 12/10, 02/11
B13: DH 8 | C13: 3 | D13: Sala 2 | E13: Seg/Qua | F13: 46314 | G13: 46349 | H13: 10 | I13: Encontro cai em feriado: 02/11
B14: DH 9 | C14: 3 | D14: Sala 1 | E14: Ter/Qui | F14: 46329 | G14: 46359 | H14: 10 | I14: —
B15: DH 10 | C15: 4 | D15: Sala 2 | E15: Ter/Qui | F15: 46329 | G15: 46359 | H15: 10 | I15: —
B16: DH 11 | C16: 4 | D16: Sala 1 | E16: Seg/Qua | F16: 46337 | G16: 46370 | H16: 10 | I16: —
B17: DH 12 | C17: 4 | D17: Sala 2 | E17: Seg/Qua | F17: 46351 | G17: 46405 | H17: 10 | I17: Atravessa o recesso institucional (21/12-08/01) — pendente de confirmação
... B20: DH 15 | C20: 5 | D20: Sala 1 | E20: Seg/Qua | F20: 46372 | G20: 46426 | H20: 10 | I20: Atravessa o recesso institucional (21/12-08/01) — pendente de confirmação
B22: Indicador | C22: Resultado | D22: Leitura
B23: Início da 1ª turma | C23: =MIN(F6:F20) | D23: Marco de início da fase de Desenvolvimento Humano
B24: Conclusão da 4ª turma | C24: =SMALL(G6:G20,4) | D24: Marco para liberar o primeiro lote de Curso Técnico (premissa: após 4 DH) — data PROPOSTA, condicionada a quórum real
B25: Conclusão da 15ª turma (todas) | C25: =MAX(G6:G20) | D25: Fim estimado da fase de Desenvolvimento Humano
B26: Duração da fase DH (dias corridos) | C26: =C25-C23+1 | D26: Da 1ª turma iniciada até a 15ª concluída
B27: Turmas ativas na mesma semana (pico) | C27: 5 | D27: Nº de turmas com o período [início,término] tocando a mesma semana corrida — NÃO é o nº de turmas se encontrando na mesma noite.
B28: Máximo de turmas na MESMA noite (mesma sala/horário) | C28: 2 | D28: Limite físico real: 2 sala(s) → no máximo 2 atividades simultâneas por noite. O uso alternado de dias (ex.: Seg/Qua com Ter/Qui) permite mais turmas ATIVAS na semana, mas não aumenta o nº de salas físicas disponíveis por noite.
B30: MARCOS DE VALIDAÇÃO DE QUÓRUM POR LOTE — formação de turma é CONDICIONADA, não automática
B31: Lote | C31: Data planejada de validação | D31: Data-limite / janela de contingência | E31: Impacto de atraso de 7 dias no lote | F31: Risco de palestra reagendada | G31: Status
B32: Lote 1 (DH 1, DH 2, DH 3) | C32: 46251 | D32: -19 dia(s) de folga antes de empurrar o lote 2 | E32: 4ª turma: +26d; fim da fase DH: +126d (considerando a folga natural entre lotes) | F32: Palestras deste lote podem precisar de reforço de mobilização/reagendamento se o quórum não fechar. | G32: Condicionado à validação
B33: Lote 2 (DH 4, DH 5, DH 6) | C33: 46267 | D33: -29 dia(s) de folga antes de empurrar o lote 3 | E33: 4ª turma: +7d; fim da fase DH: +107d (considerando a folga natural entre lotes) | F33: Palestras deste lote podem precisar de reforço de mobilização/reagendamento se o quórum não fechar. | G33: Condicionado à validação
B34: Lote 3 (DH 7, DH 8, DH 9) | C34: 46288 | D34: -30 dia(s) de folga antes de empurrar o lote 4 | E34: 4ª turma: sem mudança; fim da fase DH: +78d (considerando a folga natural entre lotes) | F34: Palestras deste lote podem precisar de reforço de mobilização/reagendamento se o quórum não fechar. | G34: Condicionado à validação
B35: Lote 4 (DH 10, DH 11, DH 12) | C35: 46322 | D35: -41 dia(s) de folga antes de empurrar o lote 5 | E35: 4ª turma: sem mudança; fim da fase DH: +48d (considerando a folga natural entre lotes) | F35: Palestras deste lote podem precisar de reforço de mobilização/reagendamento se o quórum não fechar. | G35: Condicionado à validação
B36: Lote 5 (DH 13, DH 14, DH 15) | C36: 46357 | D36: Último lote — atraso aqui só afeta o fim da fase DH | E36: 4ª turma: sem mudança; fim da fase DH: +7d (considerando a folga natural entre lotes) | F36: Palestras deste lote podem precisar de reforço de mobilização/reagendamento se o quórum não fechar. | G36: Condicionado à validação
B38: SIMULAÇÃO DE IMPACTO — ATRASO DE 7 DIAS NO LOTE 1 (ex.: quórum insuficiente nas primeiras Palestras)
B39: Cenário de folga | C39: 4ª turma concluída (original) | D39: 4ª turma concluída (com atraso) | E39: Fim da fase DH (original) | F39: Fim da fase DH (com atraso) | G39: Leitura
B40: Otimista — folgas naturais entre lotes absorvem parte do atraso | C40: 46309 | D40: 46335 | E40: 46426 | F40: 46552 | G40: 4ª turma desloca 26d; fim da fase DH desloca 126d
B41: Conservador (pior caso) — nenhuma folga é aproveitada, atraso se propaga integralmente | C41: 46309 | D41: 46316 | E41: 46426 | F41: 46433 | G41: 4ª turma desloca 7d; fim da fase DH desloca 7d

Sheet 09_CENARIO_D
B2: CENÁRIO D — 2 SALAS | DH 5x/semana
B3: Viavel, porem com pouca folga e alta intensidade diaria. | Indicação: Plano de contingencia
B5: Turma DH | C5: Lote | D5: Sala | E5: Cadência | F5: Início | G5: Término | H5: Encontros | I5: Nº aprox. de participantes | J5: Observação
B6: DH 1 | C6: 1 | D6: Sala 1 | E6: Seg-Sex | F6: 46258 | G6: 46269 | H6: 10 | I6: —
B7: DH 2 | C7: 1 | D7: Sala 2 | E7: Seg-Sex | F7: 46258 | G7: 46269 | H7: 10 | I7: —
B8: DH 3 | C8: 2 | D8: Sala 1 | E8: Seg-Sex | F8: 46273 | G8: 46286 | H8: 10 | I8: —
B9: DH 4 | C9: 2 | D9: Sala 2 | E9: Seg-Sex | F9: 46273 | G9: 46286 | H9: 10 | I9: —
B10: DH 5 | C10: 3 | D10: Sala 1 | E10: Seg-Sex | F10: 46287 | G10: 46300 | H10: 10 | I10: —
B11: DH 6 | C11: 3 | D11: Sala 2 | E11: Seg-Sex | F11: 46287 | G11: 46300 | H11: 10 | I11: —
B12: DH 7 | C12: 4 | D12: Sala 1 | E12: Seg-Sex | F12: 46301 | G12: 46315 | H12: 10 | I12: Encontro cai em feriado: 12/10
B13: DH 8 | C13: 4 | D13: Sala 2 | E13: Seg-Sex | F13: 46301 | G13: 46315 | H13: 10 | I13: Encontro cai em feriado: 12/10
B14: DH 9 | C14: 5 | D14: Sala 1 | E14: Seg-Sex | F14: 46316 | G14: 46330 | H14: 10 | I14: Encontro cai em feriado: 02/11
B15: DH 10 | C15: 5 | D15: Sala 2 | E15: Seg-Sex | F15: 46316 | G15: 46330 | H15: 10 | I15: Encontro cai em feriado: 02/11
B16: DH 11 | C16: 6 | D16: Sala 1 | E16: Seg-Sex | F16: 46331 | G16: 46344 | H16: 10 | I16: —
B17: DH 12 | C17: 6 | D17: Sala 2 | E17: Seg-Sex | F17: 46331 | G17: 46344 | H17: 10 | I17: —
... B20: DH 15 | C20: 8 | D20: Sala 1 | E20: Seg-Sex | F20: 46360 | G20: 46373 | H20: 10 | I20: —
B22: Indicador | C22: Resultado | D22: Leitura
B23: Início da 1ª turma | C23: =MIN(F6:F20) | D23: Marco de início da fase de Desenvolvimento Humano
B24: Conclusão da 4ª turma | C24: =SMALL(G6:G20,4) | D24: Marco para liberar o primeiro lote de Curso Técnico (premissa: após 4 DH) — data PROPOSTA, condicionada a quórum real
B25: Conclusão da 15ª turma (todas) | C25: =MAX(G6:G20) | D25: Fim estimado da fase de Desenvolvimento Humano
B26: Duração da fase DH (dias corridos) | C26: =C25-C23+1 | D26: Da 1ª turma iniciada até a 15ª concluída
B27: Turmas ativas na mesma semana (pico) | C27: 4 | D27: Nº de turmas com o período [início,término] tocando a mesma semana corrida — NÃO é o nº de turmas se encontrando na mesma noite.
B28: Máximo de turmas na MESMA noite (mesma sala/horário) | C28: 2 | D28: Limite físico real: 2 sala(s) → no máximo 2 atividades simultâneas por noite. O uso alternado de dias (ex.: Seg/Qua com Ter/Qui) permite mais turmas ATIVAS na semana, mas não aumenta o nº de salas físicas disponíveis por noite.
B30: MARCOS DE VALIDAÇÃO DE QUÓRUM POR LOTE — formação de turma é CONDICIONADA, não automática
B31: Lote | C31: Data planejada de validação | D31: Data-limite / janela de contingência | E31: Impacto de atraso de 7 dias no lote | F31: Risco de palestra reagendada | G31: Status
B32: Lote 1 (DH 1, DH 2) | C32: 46251 | D32: 4 dia(s) de folga antes de empurrar o lote 2 | E32: 4ª turma: +3d; fim da fase DH: sem mudança (considerando a folga natural entre lotes) | F32: Palestras deste lote podem precisar de reforço de mobilização/reagendamento se o quórum não fechar. | G32: Condicionado à validação
B33: Lote 2 (DH 3, DH 4) | C33: 46266 | D33: 1 dia(s) de folga antes de empurrar o lote 3 | E33: 4ª turma: +7d; fim da fase DH: +1d (considerando a folga natural entre lotes) | F33: Palestras deste lote podem precisar de reforço de mobilização/reagendamento se o quórum não fechar. | G33: Condicionado à validação
B34: Lote 3 (DH 5, DH 6) | C34: 46280 | D34: 1 dia(s) de folga antes de empurrar o lote 4 | E34: 4ª turma: sem mudança; fim da fase DH: +2d (considerando a folga natural entre lotes) | F34: Palestras deste lote podem precisar de reforço de mobilização/reagendamento se o quórum não fechar. | G34: Condicionado à validação
B35: Lote 4 (DH 7, DH 8) | C35: 46294 | D35: 1 dia(s) de folga antes de empurrar o lote 5 | E35: 4ª turma: sem mudança; fim da fase DH: +3d (considerando a folga natural entre lotes) | F35: Palestras deste lote podem precisar de reforço de mobilização/reagendamento se o quórum não fechar. | G35: Condicionado à validação
B36: Lote 5 (DH 9, DH 10) | C36: 46309 | D36: 1 dia(s) de folga antes de empurrar o lote 6 | E36: 4ª turma: sem mudança; fim da fase DH: +4d (considerando a folga natural entre lotes) | F36: Palestras deste lote podem precisar de reforço de mobilização/reagendamento se o quórum não fechar. | G36: Condicionado à validação
B37: Lote 6 (DH 11, DH 12) | C37: 46324 | D37: 1 dia(s) de folga antes de empurrar o lote 7 | E37: 4ª turma: sem mudança; fim da fase DH: +5d (considerando a folga natural entre lotes) | F37: Palestras deste lote podem precisar de reforço de mobilização/reagendamento se o quórum não fechar. | G37: Condicionado à validação
B38: Lote 7 (DH 13, DH 14) | C38: 46338 | D38: 1 dia(s) de folga antes de empurrar o lote 8 | E38: 4ª turma: sem mudança; fim da fase DH: +6d (considerando a folga natural entre lotes) | F38: Palestras deste lote podem precisar de reforço de mobilização/reagendamento se o quórum não fechar. | G38: Condicionado à validação
B39: Lote 8 (DH 15) | C39: 46353 | D39: Último lote — atraso aqui só afeta o fim da fase DH | E39: 4ª turma: sem mudança; fim da fase DH: +7d (considerando a folga natural entre lotes) | F39: Palestras deste lote podem precisar de reforço de mobilização/reagendamento se o quórum não fechar. | G39: Condicionado à validação
B41: SIMULAÇÃO DE IMPACTO — ATRASO DE 7 DIAS NO LOTE 1 (ex.: quórum insuficiente nas primeiras Palestras)
B42: Cenário de folga | C42: 4ª turma concluída (original) | D42: 4ª turma concluída (com atraso) | E42: Fim da fase DH (original) | F42: Fim da fase DH (com atraso) | G42: Leitura
B43: Otimista — folgas naturais entre lotes absorvem parte do atraso | C43: 46286 | D43: 46289 | E43: 46373 | F43: 46373 | G43: 4ª turma desloca 3d; fim da fase DH desloca 0d
B44: Conservador (pior caso) — nenhuma folga é aproveitada, atraso se propaga integralmente | C44: 46286 | D44: 46293 | E44: 46373 | F44: 46380 | G44: 4ª turma desloca 7d; fim da fase DH desloca 7d

Sheet 10_CRONOGRAMA_MESTRE
B2: CRONOGRAMA MESTRE DE PAULÍNIA — VISÃO COMPLETA DA EXECUÇÃO
B3: Referência: Cenário B + variante B1 de OG (NÃO confirmada). Parte dos Cursos Técnicos e da Consultoria Individual permanece programada para 2027 — ver 04_RESUMO_EXECUTIVO.
B5: Etapa | C5: Atividade / Turma | D5: Início | E5: Término | F5: Local / Sala | G5: Observação (premissa/situação)
B6: PS | C6: Palestras de Sensibilização (PS 01-30) | D6: 46245 | E6: 46310 | F6: A definir por comunidade | G6: 3x/semana (Ter/Qua/Qui), 2h cada — Confirmada
B7: DH | C7: DH 1 | D7: 46258 | E7: 46269 | F7: Sala 1 | G7: Cadência Seg-Sex — Cenário B (referência desta versão)
B8: DH | C8: DH 2 | D8: 46258 | E8: 46269 | F8: Sala 2 | G8: Cadência Seg-Sex — Cenário B (referência desta versão)
B9: DH | C9: DH 3 | D9: 46258 | E9: 46269 | F9: Sala 3 | G9: Cadência Seg-Sex — Cenário B (referência desta versão)
B10: REC | C10: Feriado: Independencia do Brasil | D10: 46272 | E10: 46272 | F10: — | G10: Confirmada (calendário municipal)
B11: DH | C11: DH 4 | D11: 46273 | E11: 46286 | F11: Sala 1 | G11: Cadência Seg-Sex — Cenário B (referência desta versão)
B12: DH | C12: DH 5 | D12: 46273 | E12: 46286 | F12: Sala 2 | G12: Cadência Seg-Sex — Cenário B (referência desta versão)
B13: DH | C13: DH 6 | D13: 46273 | E13: 46286 | F13: Sala 3 | G13: Cadência Seg-Sex — Cenário B (referência desta versão)
B14: OG | C14: OG 1 | D14: 46276 | E14: 46279 | F14: Espaço OG 1 (ADICIONAL, não confirmado) | G14: Predecessora: DH 1 — Variante B1 (espaço ADICIONAL, NÃO confirmado; ver B2 na aba 07)
B15: OG | C15: OG 2 | D15: 46276 | E15: 46279 | F15: Espaço OG 2 (ADICIONAL, não confirmado) | G15: Predecessora: DH 2 — Variante B1 (espaço ADICIONAL, NÃO confirmado; ver B2 na aba 07)
B16: OG | C16: OG 3 | D16: 46276 | E16: 46279 | F16: Espaço OG 3 (ADICIONAL, não confirmado) | G16: Predecessora: DH 3 — Variante B1 (espaço ADICIONAL, NÃO confirmado; ver B2 na aba 07)
B17: DH | C17: DH 7 | D17: 46287 | E17: 46300 | F17: Sala 1 | G17: Cadência Seg-Sex — Cenário B (referência desta versão)
... B55: CT | C55: CT4b — Preparacao de Alimentos | D55: 46405 | E55: 46422 | F55: Fundo Social / SENAC | G55: Data proposta para simulação — pendente de quórum, contratação e validação do fornecedor
B57: LEGENDA
C58: PS - Palestra de Sensibilização
C59: DH - Desenvolvimento Humano
C60: OG - Oficina de Gestão
C61: CT - Curso Técnico
C62: EAD - Curso Online
C63: CI - Consultoria Individual
C64: REC - Recesso / feriado

Sheet 11_AGENDA_POR_SALA
B2: AGENDA POR SALA — SEM SOBREPOSIÇÃO CONFIRMADA (checagem dia a dia por cadência real)
B3: Cenário B: 3 salas de DH. Duas variantes de OG mostradas lado a lado (B1: espaço adicional NÃO confirmado; B2: mesmas salas do DH).
B5: SALAS DE DH
B6: Sala | C6: Turma | D6: Tipo | E6: Início | F6: Término | G6: Cadência | H6: Conflito de horário? | I6: Observação
B7: Sala 1 | C7: DH 1 | D7: DH | E7: 46258 | F7: 46269 | G7: Seg-Sex | H7: Não (verificado dia a dia por cadência)
B8: Sala 2 | C8: DH 2 | D8: DH | E8: 46258 | F8: 46269 | G8: Seg-Sex | H8: Não (verificado dia a dia por cadência)
B9: Sala 3 | C9: DH 3 | D9: DH | E9: 46258 | F9: 46269 | G9: Seg-Sex | H9: Não (verificado dia a dia por cadência)
B10: Sala 1 | C10: DH 4 | D10: DH | E10: 46273 | F10: 46286 | G10: Seg-Sex | H10: Não (verificado dia a dia por cadência)
B11: Sala 2 | C11: DH 5 | D11: DH | E11: 46273 | F11: 46286 | G11: Seg-Sex | H11: Não (verificado dia a dia por cadência)
B12: Sala 3 | C12: DH 6 | D12: DH | E12: 46273 | F12: 46286 | G12: Seg-Sex | H12: Não (verificado dia a dia por cadência)
B13: Sala 1 | C13: DH 7 | D13: DH | E13: 46287 | F13: 46300 | G13: Seg-Sex | H13: Não (verificado dia a dia por cadência)
B14: Sala 2 | C14: DH 8 | D14: DH | E14: 46287 | F14: 46300 | G14: Seg-Sex | H14: Não (verificado dia a dia por cadência)
B15: Sala 3 | C15: DH 9 | D15: DH | E15: 46287 | F15: 46300 | G15: Seg-Sex | H15: Não (verificado dia a dia por cadência)
B16: Sala 1 | C16: DH 10 | D16: DH | E16: 46301 | F16: 46315 | G16: Seg-Sex | H16: Não (verificado dia a dia por cadência)
B17: Sala 2 | C17: DH 11 | D17: DH | E17: 46301 | F17: 46315 | G17: Seg-Sex | H17: Não (verificado dia a dia por cadência)
B18: Sala 3 | C18: DH 12 | D18: DH | E18: 46301 | F18: 46315 | G18: Seg-Sex | H18: Não (verificado dia a dia por cadência)
... B21: Sala 3 | C21: DH 15 | D21: DH | E21: 46316 | F21: 46330 | G21: Seg-Sex | H21: Não (verificado dia a dia por cadência)
B23: VARIANTE B1 — OG EM ESPAÇOS ADICIONAIS (NÃO CONFIRMADO)
B24: Espaço | C24: Turma | D24: Tipo | E24: Início | F24: Término | G24: Cadência | H24: Conflito de horário? | I24: Observação
B25: Espaço OG 1 (ADICIONAL, não confirmado) | C25: OG 1 | D25: OG | E25: 46276 | F25: 46279 | G25: Seg-Sex (2 enc.) | H25: Não (espaço dedicado)
B26: Espaço OG 1 (ADICIONAL, não confirmado) | C26: OG 4 | D26: OG | E26: 46293 | F26: 46294 | G26: Seg-Sex (2 enc.) | H26: Não (espaço dedicado)
B27: Espaço OG 1 (ADICIONAL, não confirmado) | C27: OG 7 | D27: OG | E27: 46308 | F27: 46309 | G27: Seg-Sex (2 enc.) | H27: Não (espaço dedicado)
B28: Espaço OG 1 (ADICIONAL, não confirmado) | C28: OG 10 | D28: OG | E28: 46322 | F28: 46323 | G28: Seg-Sex (2 enc.) | H28: Não (espaço dedicado)
B29: Espaço OG 1 (ADICIONAL, não confirmado) | C29: OG 13 | D29: OG | E29: 46337 | F29: 46338 | G29: Seg-Sex (2 enc.) | H29: Não (espaço dedicado)
B30: Espaço OG 2 (ADICIONAL, não confirmado) | C30: OG 2 | D30: OG | E30: 46276 | F30: 46279 | G30: Seg-Sex (2 enc.) | H30: Não (espaço dedicado)
B31: Espaço OG 2 (ADICIONAL, não confirmado) | C31: OG 5 | D31: OG | E31: 46293 | F31: 46294 | G31: Seg-Sex (2 enc.) | H31: Não (espaço dedicado)
B32: Espaço OG 2 (ADICIONAL, não confirmado) | C32: OG 8 | D32: OG | E32: 46308 | F32: 46309 | G32: Seg-Sex (2 enc.) | H32: Não (espaço dedicado)
B33: Espaço OG 2 (ADICIONAL, não confirmado) | C33: OG 11 | D33: OG | E33: 46322 | F33: 46323 | G33: Seg-Sex (2 enc.) | H33: Não (espaço dedicado)
B34: Espaço OG 2 (ADICIONAL, não confirmado) | C34: OG 14 | D34: OG | E34: 46337 | F34: 46338 | G34: Seg-Sex (2 enc.) | H34: Não (espaço dedicado)
B35: Espaço OG 3 (ADICIONAL, não confirmado) | C35: OG 3 | D35: OG | E35: 46276 | F35: 46279 | G35: Seg-Sex (2 enc.) | H35: Não (espaço dedicado)
B36: Espaço OG 3 (ADICIONAL, não confirmado) | C36: OG 6 | D36: OG | E36: 46293 | F36: 46294 | G36: Seg-Sex (2 enc.) | H36: Não (espaço dedicado)
... B39: Espaço OG 3 (ADICIONAL, não confirmado) | C39: OG 15 | D39: OG | E39: 46337 | F39: 46338 | G39: Seg-Sex (2 enc.) | H39: Não (espaço dedicado)
B41: VARIANTE B2 — OG NAS MESMAS 3 SALAS DE DH (após o fim total da fase DH)
B42: Sala | C42: Turma | D42: Tipo | E42: Início | F42: Término | G42: Cadência | H42: Conflito de horário? | I42: Observação
B43: Sala 1 | C43: OG 1 | D43: OG | E43: 46331 | F43: 46332 | G43: Seg-Sex (2 enc.) | H43: Não (roda em ondas sequenciais)
B44: Sala 1 | C44: OG 4 | D44: OG | E44: 46335 | F44: 46336 | G44: Seg-Sex (2 enc.) | H44: Não (roda em ondas sequenciais)
B45: Sala 1 | C45: OG 7 | D45: OG | E45: 46337 | F45: 46338 | G45: Seg-Sex (2 enc.) | H45: Não (roda em ondas sequenciais)
B46: Sala 1 | C46: OG 10 | D46: OG | E46: 46339 | F46: 46342 | G46: Seg-Sex (2 enc.) | H46: Não (roda em ondas sequenciais)
B47: Sala 1 | C47: OG 13 | D47: OG | E47: 46343 | F47: 46344 | G47: Seg-Sex (2 enc.) | H47: Não (roda em ondas sequenciais)
B48: Sala 2 | C48: OG 2 | D48: OG | E48: 46331 | F48: 46332 | G48: Seg-Sex (2 enc.) | H48: Não (roda em ondas sequenciais)
...

Sheet 12_TURMAS_DH
B2: VISÃO POR TURMA — PALESTRAS (PS) E DESENVOLVIMENTO HUMANO (DH)
B3: Cenário B (referência desta versão) — a formação de cada turma é CONDICIONADA à Palestra atingir quórum (ver marcos de validação na aba 07)
B5: PALESTRAS DE SENSIBILIZAÇÃO (PS 01 – PS 30)
B6: Turma | C6: Data | D6: Dia da semana | E6: Carga horária | F6: Encontros | G6: Nº aprox. participantes | H6: Predecessora | I6: Situação da informação
B7: PS 01 | C7: 46245 | D7: Terça | E7: 2h | F7: 1 | G7: 20-40 | H7: — | I7: Premissa provisória
B8: PS 02 | C8: 46246 | D8: Quarta | E8: 2h | F8: 1 | G8: 20-40 | H8: — | I8: Premissa provisória
B9: PS 03 | C9: 46247 | D9: Quinta | E9: 2h | F9: 1 | G9: 20-40 | H9: — | I9: Premissa provisória
B10: PS 04 | C10: 46252 | D10: Terça | E10: 2h | F10: 1 | G10: 20-40 | H10: — | I10: Premissa provisória
B11: PS 05 | C11: 46253 | D11: Quarta | E11: 2h | F11: 1 | G11: 20-40 | H11: — | I11: Premissa provisória
B12: PS 06 | C12: 46254 | D12: Quinta | E12: 2h | F12: 1 | G12: 20-40 | H12: — | I12: Premissa provisória
B13: PS 07 | C13: 46259 | D13: Terça | E13: 2h | F13: 1 | G13: 20-40 | H13: — | I13: Premissa provisória
B14: PS 08 | C14: 46260 | D14: Quarta | E14: 2h | F14: 1 | G14: 20-40 | H14: — | I14: Premissa provisória
B15: PS 09 | C15: 46261 | D15: Quinta | E15: 2h | F15: 1 | G15: 20-40 | H15: — | I15: Premissa provisória
B16: PS 10 | C16: 46266 | D16: Terça | E16: 2h | F16: 1 | G16: 20-40 | H16: — | I16: Premissa provisória
B17: PS 11 | C17: 46267 | D17: Quarta | E17: 2h | F17: 1 | G17: 20-40 | H17: — | I17: Premissa provisória
B18: PS 12 | C18: 46268 | D18: Quinta | E18: 2h | F18: 1 | G18: 20-40 | H18: — | I18: Premissa provisória
