Workbook

Sheet 00_LEIA-ME
B2: PARTIU! APRENDER E EMPREENDER — CRONOGRAMA PAULÍNIA (NÚCLEO 2)
B3: Instituto da Criança · Sebrae · Petrobras — Material de apoio à decisão e negociação | Gerado em 21/07/2026
B5: O QUE É ESTE ARQUIVO
B6: Este arquivo consolida e cruza 4 documentos-fonte recebidos sobre o projeto em Paulínia: (1) a apresentação macro do projeto com metas contratuais; (2) a planilha operacional de turmas/cargas horárias; (3) uma tentativa anterior de cronograma da coordenação; e (4) uma simulação inicial de 4 cenários de salas/frequência do Desenvolvimento Humano (DH). Os 4 arquivos originais NÃO foram alterados. Onde os documentos divergem, a divergência foi preservada e classificada — nenhum número foi escolhido "por conta própria" sem sinalização.
B10: COMO CLASSIFICAMOS CADA INFORMAÇÃO
B11: Confirmada | C11: Valor igual em pelo menos 2 fontes independentes, sem contradição.
B12: Premissa provisória | C12: Valor usado para construir o cronograma na ausência de confirmação formal; pode mudar.
B13: Divergência entre documentos | C13: Os documentos-fonte trazem valores diferentes para o mesmo item; nenhum foi descartado.
B14: Informação pendente de validação | C14: Dado ausente, incompleto ou com placeholder (ex.: fornecedor "?").
B15: Decisão recomendada | C15: Recomendação da análise, com justificativa — não é um fato, é uma sugestão de encaminhamento.
B17: COMO NAVEGAR
B18: 01_PREMISSAS | C18: Painel de premissas editáveis (células amarelas). Altere aqui frequência de DH, nº de salas, carga horária etc.
B19: 02_DIVERGENCIAS | C19: Tabela completa de conflitos entre os 4 documentos, com decisão provisória e responsável pela validação.
B20: 03_FLUXO_DA_TRILHA | C20: Mapa da trilha PS → DH → OG → CT → EAD → CI, com as regras quantitativas encontradas (e o que é premissa).
B21: 04_RESUMO_EXECUTIVO | C21: Visão de 1 página para Sebrae/Petrobras — leitura em menos de 2 minutos.
B22: 05_COMPARATIVO_CENARIOS | C22: Painel comparativo dos 4 cenários de sala/frequência do DH, com semáforo de viabilidade.
B23: 06 a 09_CENARIO A-D | C23: Detalhamento turma a turma de cada cenário de DH (datas, sala, cadência).
B24: 10_CRONOGRAMA_MESTRE | C24: Linha do tempo completa de Paulínia no cenário recomendado (PS, DH, OG, CT, EAD, CI, recesso, feriados).
B25: 11_AGENDA_POR_SALA | C25: Ocupação de Sala 1/2/3 e locais de curso técnico, sem sobreposição.
B26: 12_TURMAS_DH | C26: Detalhamento de PS 01-30 e DH 01-15 (datas, frequência, carga horária, participantes, predecessora).
B27: 13_OFICINAS_GESTAO | C27: Detalhamento das turmas de Oficina de Gestão.
B28: 14_CURSOS_TECNICOS | C28: Detalhamento das turmas de curso técnico (tema, fornecedor, carga horária, participantes).
B29: 15_EAD_CONSULTORIAS | C29: Curso EAD e Consultoria Individual.
... B31: 17_GANTT_EXECUTIVO | C31: Gantt visual semanal de toda a trilha (cenário recomendado) com feriados e recesso destacados.
B33: REGRAS IMPORTANTES DESTE MODELO
B34: ⚠ | C34: Nenhuma divergência foi corrigida silenciosamente (ex.: 20h x 22h de DH; 10 x 13 turmas de curso técnico).
B35: ⚠ | C35: Toda data calculada indica, na própria linha, qual premissa foi usada para chegar até ela.
B36: ⚠ | C36: As datas são datas reais do Excel (não texto) — podem ser usadas em fórmulas, filtros e classificação.
B37: ⚠ | C37: As abas 05 (comparativo) recalculam automaticamente a partir das abas 06-09 via fórmulas (MIN/MÁXIMO/MENOR).
B38: ⚠ | C38: As grades turma a turma (06-09, 10, 11, 12-15) são geradas a partir das premissas vigentes no momento da montagem. Se uma premissa estrutural mudar (ex.: nº de salas, frequência do DH), regenere o arquivo para recalcular as grades — o Excel nativo não recalcula sozinho um algoritmo de alocação de salas.

Sheet 01_PREMISSAS
B2: PREMISSAS DO CRONOGRAMA — CÉLULAS AMARELAS SÃO EDITÁVEIS
B3: Alterar aqui atualiza automaticamente as datas e indicadores das abas 04 e 05. Grades turma a turma (06-17) exigem regeneração do arquivo.
B5: PALESTRAS DE SENSIBILIZAÇÃO (PS)
B6: Item | C6: Valor | D6: Observação / Classificação | E6: Status
B7: Data de início | C7: 46245 | D7: Confirmado em 3 fontes (planilha operacional, simulação, cronograma anterior) | E7: Confirmada
B8: Data-alvo de término | C8: 46310 | D8: Confirmado em 3 fontes | E8: Confirmada
B9: Total de turmas (Paulínia) | C9: 30 | D9: Base operacional J3=30; PDF macro Núcleo 2 = 30 turmas | E9: Confirmada
B10: Frequência | C10: 3x/semana (Ter/Qua/Qui) | D10: Cadência dedutível da planilha "Possibilidades"; concilia início e fim informados | E10: Premissa provisória
B11: Carga horária por sessão | C11: 2h | D11: Planilha operacional E3 | E11: Confirmada
B13: DESENVOLVIMENTO HUMANO (DH)
B14: Item | C14: Valor | D14: Observação / Classificação | E14: Status
B15: Total de turmas (Paulínia) | C15: 15 | D15: Confirmado: planilha operacional J4, PDF macro Núcleo 2, simulação de cenários | E15: Confirmada
B16: Carga horária total — OPÇÃO USADA NO MODELO | C16: 20h / 10 encontros | D16: Usada pela simulação de cenários e citada em reunião (Sebrae teria reduzido) | E16: Premissa provisória
B17: Carga horária total — OPÇÃO ALTERNATIVA (documental) | C17: 22h / 11 encontros | D17: Planilha operacional (F4=22, G4=11) e carga horária citada no PDF macro ("22 horas") | E17: Divergência entre documentos
B18: Mínimo de participantes/turma | C18: 20 | D18: Planilha operacional H4; PDF usa 20/turma como média de referência | E18: Confirmada
B19: Máximo de participantes/turma | C19: 40 | D19: Planilha operacional I4 | E19: Confirmada
B20: Regra de formação — OPÇÃO A | C20: 2 PS = 1 DH | D20: Fecha exatamente com 30 PS → 15 DH; é a regra usada nesta simulação | E20: Premissa provisória
B21: Regra de formação — OPÇÃO B (anotação divergente) | C21: 4 OS = 1 DH | D21: "OS" não existe na trilha; provável erro de digitação de "PS". Mesmo lendo como "4 PS=1DH", o resultado (7-8 turmas) não fecha com as 15 turmas confirmadas | E21: Divergência entre documentos
B22: Frequência semanal a comparar | C22: 2x ou 5x por semana | D22: Ambas exigidas pelo escopo desta análise (cenários A-D) | E22: Premissa provisória
B23: Nº de salas a comparar | C23: 2 ou 3 | D23: Ambas exigidas pelo escopo desta análise (cenários A-D) | E23: Premissa provisória
B24: Gatilho para 1º curso técnico | C24: Após a 4ª turma de DH concluída | D24: Planilha operacional, anotação A34 | E24: Premissa provisória
B26: OFICINA DE GESTÃO (OG)
B27: Item | C27: Valor | D27: Observação / Classificação | E27: Status
B28: Total de turmas — OPÇÃO USADA NO MODELO | C28: 15 | D28: Planilha operacional J5=15 (1 OG por turma de DH concluída) | E28: Premissa provisória
B29: Total de turmas — LEITURA ALTERNATIVA | C29: ≈7 a 8 | D29: Se a anotação "2 DH = 1 OG + 1 CT" (A28) for aplicada literalmente às 15 turmas de DH | E29: Divergência entre documentos
B30: Carga horária total | C30: 4h | D30: Planilha operacional F5 | E30: Confirmada
B31: Encontros | C31: 2 | D31: Planilha operacional G5, de 2h cada | E31: Confirmada
B32: Mínimo/máximo de participantes | C32: 15 / 18 | D32: Planilha operacional H5/I5 | E32: Confirmada
B33: Espaço para a OG no cenário recomendado (B) | C33: 3 espaços dedicados, distintos das 3 salas de DH | D33: ACHADO DESTA ANÁLISE: no cenário B (3 salas, DH 5x/semana), as 3 salas de DH ficam 100% ocupadas por lotes consecutivos durante toda a fase — não sobra horário livre na mesma sala para a OG. É preciso um espaço adicional. | E33: Decisão recomendada
B35: CURSOS TÉCNICOS (CT)
B36: Item | C36: Valor | D36: Observação / Classificação | E36: Status
B37: Total de turmas — OPÇÃO USADA NO MODELO | C37: 10 | D37: Planilha operacional: soma de J6:J12 (7 temas) | E37: Premissa provisória
B38: Total de turmas — META CONTRATUAL (PDF macro) | C38: 13 | D38: PDF "Apres. Projeto e Anexos", Núcleo 2 = 13 turmas = 195 pessoas | E38: Divergência entre documentos
B39: Diferença a validar | C39: 3 turmas | D39: Não foi definido neste material qual(is) tema(s) receberia(m) turma adicional para fechar 13 | E39: Informação pendente de validação
B40: Frequência | C40: 5x/semana, 4h/dia | D40: Planilha operacional (observação) e confirmado no briefing | E40: Confirmada
B41: Turno preferencial | C41: Noite | D41: Confirmado na planilha operacional e no briefing | E41: Confirmada
B42: Quórum mínimo por turma | C42: 14 a 18 (varia por curso/fornecedor) | D42: Planilha operacional H6:H12; reunião cita 16 como referência geral | E42: Divergência entre documentos
B44: EAD E CONSULTORIA INDIVIDUAL
B45: Item | C45: Valor | D45: Observação / Classificação | E45: Status
B46: EAD — carga horária | C46: 6h / 3 encontros | D46: Planilha operacional linha 13 | E46: Confirmada
...

Sheet 02_DIVERGENCIAS
B2: DIVERGÊNCIAS ENTRE OS 4 DOCUMENTOS — NADA FOI CORRIGIDO SILENCIOSAMENTE
B3: Toda linha aponta os documentos envolvidos, o impacto no cronograma e uma decisão provisória — a validar com Sebrae/Instituto
B5: Tema | C5: Divergência encontrada | D5: Documentos envolvidos | E5: Valores em conflito | F5: Impacto no cronograma | G5: Decisão recomendada (provisória) | H5: Classificação
B6: Carga horária do DH | C6: Planilha operacional e PDF contratual indicam 22h/11 encontros; reunião recente relata redução para 20h pelo Sebrae, sem documento formal. | D6: Proposta (xlsx) + PDF macro vs. ata de reunião / Simulação de cenários | E6: 22h / 11 encontros vs. 20h / 10 encontros | F6: Muito alto: cada turma de DH muda ±1 semana de duração; em 15 turmas encadeadas, o efeito acumulado desloca o início dos cursos técnicos e o fim da fase DH em várias semanas. | G6: Usar 20h/10 encontros apenas como premissa de trabalho (é o que consta na simulação mais recente), mas obter confirmação formal por escrito do Sebrae antes de compromissar datas com a Petrobras. | H6: Divergência entre documentos
B7: Quantidade de turmas de Curso Técnico | C7: O documento macro contratual (Anexos do projeto) indica 13 turmas para o Núcleo 2 (Paulínia); a planilha operacional detalhada soma apenas 10 turmas nos 7 temas listados. | D7: PDF "Apres. Projeto e Anexos 01.2026" vs. Proposta (xlsx) | E7: 13 turmas (meta contratual) vs. 10 turmas (planilha operacional) | F7: Muito alto: se 13 for a meta válida, faltam 3 turmas/fornecedores a contratar, o que desloca o fim da fase de cursos técnicos e a meta de 195 participantes. | G7: Levantar com a coordenação quais 3 turmas adicionais fariam sentido (ex.: 2ª turma de Automação e Jardinagem, ou nova Beleza/Cabelos) e formalizar com os fornecedores antes de assumir 13 como meta. | H7: Divergência entre documentos
B8: Regra de formação do DH a partir das Palestras | C8: A planilha operacional traz duas anotações conflitantes na mesma aba: "2 PS = 1 DH" (fecha com 15 turmas) e "4 OS = 1 DH" (não fecha; "OS" não corresponde a nenhuma sigla da trilha). | D8: Proposta (xlsx), observações A27 e A30 | E8: 2 PS = 1 DH vs. 4 OS = 1 DH | F8: Alto: define o ritmo de liberação de novos lotes de DH; usar a regra errada muda a data de abertura de cada turma. | G8: Adotar "2 PS = 1 DH" (única leitura que fecha com as 15 turmas confirmadas) e tratar "4 OS = 1 DH" como possível erro de digitação a confirmar com quem escreveu a anotação original. | H8: Divergência entre documentos
B9: Regra de composição da Oficina de Gestão e Curso Técnico | C9: A planilha operacional lista 15 turmas de OG (1 para cada DH), mas também traz a anotação "2 DH = 1 OG + 1 CT", que implicaria só ~7-8 turmas de OG para 15 DH. | D9: Proposta (xlsx), linha J5 vs. observação A28 | E9: 15 turmas de OG (1:1 com DH) vs. ~7-8 turmas de OG (1 a cada 2 DH) | F9: Muito alto: dobra ou reduz pela metade a necessidade de salas/horários de OG, afetando toda a fase seguinte à DH. | G9: Confirmar com a coordenação se cada turma de DH forma sua própria OG (15 no total) ou se as turmas de DH são pareadas antes da OG (aprox. 7-8 no total). | H9: Divergência entre documentos
B10: Quórum mínimo dos cursos técnicos | C10: A planilha operacional traz mínimos de 14 ou 15 participantes por turma, variando por curso; a reunião menciona 16 como referência geral. | D10: Proposta (xlsx), coluna H vs. ata de reunião | E10: 14-15 (planilha, por curso) vs. 16 (reunião, geral) | F10: Alto: se 16 for o piso real exigido pelos fornecedores, pode faltar gente inscrita quando 4 turmas de DH (≈80 pessoas) alimentam 2 turmas técnicas. | G10: Confirmar o mínimo por fornecedor/curso antes de fechar contratos, em vez de aplicar um número único a todos os cursos. | H10: Divergência entre documentos
B11: Disponibilidade de salas para o DH | C11: O cronograma anterior da coordenação foi desenhado com 3 salas simultâneas; a discussão mais recente também cogita apenas 2 salas. | D11: "Possibilidades de Cronograma" (título da aba: "3 Salas Simultâneas") vs. briefing / Simulação de cenários | E11: 3 salas vs. 2 salas | F11: Muito alto: é a variável que mais muda a duração total da fase de DH (73 dias com 3 salas/5x semana vs. 169 dias com 2 salas/2x semana). | G11: Confirmar com antecedência a disponibilidade real e exclusiva de salas à noite antes de comunicar datas ao Sebrae — ver comparativo de cenários na aba 05. | H11: Divergência entre documentos
B12: Recesso institucional | C12: A simulação de cenários bloqueia o período de 21/12/2026 a 08/01/2027 como recesso, mas não há confirmação formal de que o Instituto/Sebrae adotarão esse recesso. | D12: Simulação de cenários (aba "Premissas e Pendências") | E12: 21/12/2026 a 08/01/2027 (assumido) vs. nenhuma confirmação | F12: Médio: cenários que já se estendem para dezembro/janeiro (C e D) ficam ainda mais espremidos ou mais longos conforme o recesso seja confirmado ou não. | G12: Confirmar a duração exata do recesso institucional 2026/2027 junto à coordenação administrativa. | H12: Informação pendente de validação
B13: Datas com ano incorreto no cronograma anterior | C13: A aba "Paulínia" do arquivo "Possibilidades de Cronograma" tem uma seção rotulada "Janeiro de 2027" cujas datas de calendário estão grafadas como 2026 (ex.: célula D152 = 04/01/2026), e ao menos uma linha traz data de término anterior à de início (N13 = 05/12/2026 x O13 = 18/11/2026). | D13: "Possibilidades de Cronograma- Paulínia.xlsx", aba Paulínia | E13: Rótulo "Janeiro de 2027" com datas grafadas 2026; DHP9 com fim (18/11) anterior ao início (05/12) | F13: Alto: se usado como referência sem correção, o leitor pode interpretar as datas de janeiro como se fossem no ano errado, ou aceitar uma janela de datas invertida. | G13: Não usar essa planilha como fonte de datas finais; tratá-la apenas como registro histórico da tentativa anterior (preservada, sem edição, no arquivo original). | H13: Divergência entre documentos
B14: Fornecedor do curso de Jardinagem | C14: O cronograma anterior da coordenação registra o fornecedor do curso de Jardinagem como "?" — não definido. | D14: "Possibilidades de Cronograma- Paulínia.xlsx", célula R48 | E14: Fornecedor: "?" | F14: Alto: sem fornecedor confirmado, a turma de Jardinagem não pode ser efetivamente contratada nem ter data de início garantida. | G14: Priorizar a definição do fornecedor de Jardinagem antes de comunicar a data desta turma aos participantes. | H14: Informação pendente de validação
B15: Meta de participantes por turma de DH: valor único ou faixa | C15: O PDF macro usa "20 pessoas por turma" como parâmetro único de cálculo de metas; a planilha operacional define uma faixa de 20 a 40. | D15: PDF "Apres. Projeto e Anexos" vs. Proposta (xlsx), colunas H4/I4 | E15: 20 pessoas/turma (fixo, para cálculo de meta) vs. 20 a 40 (faixa operacional) | F15: Baixo a médio: não é contraditório em si (20 pode ser a média usada para a meta), mas pode gerar expectativa de turmas menores do que a operação permite. | G15: Comunicar a meta com a faixa completa (20-40) para não subdimensionar a expectativa de vagas. | H15: Informação pendente de validação

Sheet 03_FLUXO_DA_TRILHA
B2: FLUXO DA TRILHA — PALESTRA → DH → OFICINA DE GESTÃO → CURSO TÉCNICO → EAD → CONSULTORIA
B3: Sequência obrigatória de dependências. Regras quantitativas mostradas como premissa/divergência, nunca como fato quando não confirmadas.
B5: PALESTRA DE SENSIBILIZAÇÃO (PS) | E5: DESENVOLVIMENTO HUMANO (DH) | H5: OFICINA DE GESTÃO (OG) | K5: CURSO TÉCNICO (CT) | N5: CURSO EAD | Q5: CONSULTORIA INDIVIDUAL (CI)
D6: → | G6: → | J6: → | M6: → | P6: →
B8: 30 turmas | E8: 15 turmas | H8: 15 turmas* | K8: 10 turmas* | N8: contínuo | Q8: meta 150 pessoas
B10: * Ver divergência quantitativa nas abas 01 e 02 (OG: 15 x ~7-8; CT: 10 x 13).
B12: Relação quantitativa citada nos documentos | F12: Fecha com os totais confirmados (30 PS / 15 DH)? | J12: Classificação
B13: 30 PS → 15 DH (regra: 2 PS = 1 DH) | F13: Sim — 30 ÷ 2 = 15, bate exatamente com o total confirmado. | J13: Confirmada
B14: 30 PS → 15 DH (regra: 4 OS = 1 DH) | F14: Não — 30 ÷ 4 = 7,5, não bate com 15 turmas. Sigla "OS" também não existe na trilha (possível erro de digitação de "PS"). | J14: Divergência entre documentos
B15: 4 DH concluídos → 2 turmas de Curso Técnico (~80 pessoas formando 2 turmas de ~15-18) | F15: Aritmeticamente aproximado (80 pessoas / 2 turmas = 40 cada, acima do quórum de 14-18 por turma); indica que nem todos os 80 formandos migram para o mesmo curso técnico — a real distribuição depende da escolha individual de curso. | J15: Premissa provisória
B16: 2 DH = 1 OG + 1 CT | F16: Não fecha com as 15 turmas de OG citadas na planilha operacional (implicaria ~7-8 OG, não 15). | J16: Divergência entre documentos
B17: 15 DH → 15 OG (1 para 1) | F17: Consistente com o total de 15 turmas de OG da planilha operacional, mas contradiz a regra "2 DH = 1 OG + 1 CT" acima. | J17: Premissa provisória
B19: LEGENDA DE ETAPAS
C20: PS - Palestra de Sensibilização
C21: DH - Desenvolvimento Humano
C22: OG - Oficina de Gestão
C23: CT - Curso Técnico
C24: EAD - Curso Online
C25: CI - Consultoria Individual
C26: Recesso / feriado

Sheet 04_RESUMO_EXECUTIVO
B2: PARTIU! APRENDER E EMPREENDER — PAULÍNIA
B3: Trilha completa: Palestra de Sensibilização → Desenvolvimento Humano → Oficina de Gestão → Curso Técnico → EAD → Consultoria Individual
B5: PERÍODO TOTAL: 11/08/2026 a 06/03/2027 (cenário recomendado)
B7: Início das Palestras | C7: Início do DH | D7: 4ª turma de DH concluída | E7: 1º Curso Técnico possível | F7: Fim do DH (15 turmas) | G7: Fim dos Cursos Técnicos
B8: 46245 | C8: 46258 | D8: 46286 | E8: 46293 | F8: 46330 | G8: 46422
B10: LINHA DO TEMPO — CENÁRIO RECOMENDADO (B: 3 SALAS, DH 5X/SEMANA)
B11: Etapa | C11: AUG/26 | D11: SEP/26 | E11: OCT/26 | F11: NOV/26 | G11: DEC/26 | H11: JAN/27 | I11: FEB/27
B12: Palestras de Sensibilização
B13: Desenvolvimento Humano
B14: Oficina de Gestão
B15: Cursos Técnicos
B16: Curso EAD
B17: Consultoria Individual
B18: Recesso / feriados
B20: CENÁRIO RECOMENDADO PARA NEGOCIAÇÃO: 3 SALAS, DH 5X/SEMANA Conclui o Desenvolvimento Humano em 73 dias (24/08 a 04/11/2026) — o mais rápido entre os 4 cenários avaliados — liberando o maior tempo possível para Oficina de Gestão, Cursos Técnicos, EAD e Consultoria Individual ainda dentro do ano, sem cruzar o recesso institucional. Alternativa de contingência: Cenário D (2 salas, DH 5x/semana).
B24: LEGENDA
C25: Palestras de Sensibilização | E25: Desenvolvimento Humano | G25: Oficina de Gestão | I25: Cursos Técnicos | K25: Curso EAD | M25: Consultoria Individual | O25: Recesso/feriado
B27: Datas construídas a partir de premissas explicitadas nas abas 01, 02 e 03 deste arquivo — sujeitas a confirmação formal do Sebrae/Instituto.

Sheet 05_COMPARATIVO_CENARIOS
B2: COMPARATIVO DOS 4 CENÁRIOS DE DESENVOLVIMENTO HUMANO (DH)
B3: Salas x Frequência semanal — indicadores recalculados por fórmula a partir das abas 06 a 09
B5: Cenário | C5: Salas | D5: Frequência DH | E5: Capacidade simultânea | F5: Início do DH | G5: 4ª turma concluída | H5: 15ª turma concluída | I5: Duração fase DH (dias) | J5: Riscos principais | K5: Vantagens / Desvantagens | L5: Viabilidade | M5: Recomendação
B6: Cenário A | C6: 3 | D6: 2x/semana | E6: ='06_CENARIO_A'!C27 | F6: ='06_CENARIO_A'!C23 | G6: ='06_CENARIO_A'!C24 | H6: ='06_CENARIO_A'!C25 | I6: ='06_CENARIO_A'!C26 | J6: Sobreposição de turmas exige interleaving de dias (Seg/Qua com Ter/Qui) na mesma sala; termina em dezembro, próximo ao recesso. | K6: Vantagem: usa a capacidade máxima das 3 salas. Desvantagem: ritmo mais lento (2x/semana) atrasa toda a cadeia OG→CT→EAD→CI. | L6: Viável
B7: Cenário B ★ | C7: 3 | D7: 5x/semana | E7: ='07_CENARIO_B'!C27 | F7: ='07_CENARIO_B'!C23 | G7: ='07_CENARIO_B'!C24 | H7: ='07_CENARIO_B'!C25 | I7: ='07_CENARIO_B'!C26 | J7: Ritmo intenso (5x/semana) exige disponibilidade constante de facilitadores e das 3 salas em sequência apertada entre lotes. | K7: Vantagem: conclui a fase DH mais cedo (04/11), maximizando o tempo disponível para OG, CT, EAD e CI antes do fim do ano. Desvantagem: menor margem de faltas/reposição por turma (10 dias úteis corridos). | L7: Altamente viável
B8: Cenário C | C8: 2 | D8: 2x/semana | E8: ='08_CENARIO_C'!C27 | F8: ='08_CENARIO_C'!C23 | G8: ='08_CENARIO_C'!C24 | H8: ='08_CENARIO_C'!C25 | I8: ='08_CENARIO_C'!C26 | J8: Fase DH ultrapassa o recesso institucional e só termina em fevereiro/2027 — compromete seriamente o início dos cursos técnicos e a meta anual. | K8: Vantagem: nenhuma relevante frente aos demais cenários. Desvantagem: menor capacidade simultânea (4) e maior duração total (169 dias). | L8: Não recomendado
B9: Cenário D | C9: 2 | D9: 5x/semana | E9: ='09_CENARIO_D'!C27 | F9: ='09_CENARIO_D'!C23 | G9: ='09_CENARIO_D'!C24 | H9: ='09_CENARIO_D'!C25 | I9: ='09_CENARIO_D'!C26 | J9: Alta intensidade diária (5x/semana) combinada a apenas 2 salas deixa pouquíssima folga para reposição de encontros perdidos. | K9: Vantagem: mais rápido que os cenários de 2x/semana. Desvantagem: capacidade simultânea mínima (2) entre os 4 cenários. | L9: Viável com ressalvas
B11: RECOMENDAÇÃO: Cenário B (3 salas, DH 5x/semana) — conclui a fase de Desenvolvimento Humano em 04/11/2026, liberando o maior tempo possível para Oficina de Gestão, Cursos Técnicos, EAD e Consultoria Individual ainda dentro do ano civil, antes do recesso institucional. Justificativa: menor duração total da fase (73 dias), maior antecedência da 4ª turma concluída (21/09, a mais cedo entre os 4 cenários) e nenhuma sobreposição com o recesso. Ressalva: exige confirmação de disponibilidade das 3 salas e de facilitadores em ritmo diário.

Sheet 06_CENARIO_A
B2: CENÁRIO A — 3 SALAS | DH 2x/semana
B3: Viavel, mas com maior sobreposicao e termino em dezembro. | Indicação: Alternativa equilibrada
B5: Turma DH | C5: Lote | D5: Sala | E5: Cadência | F5: Início | G5: Término | H5: Encontros | I5: Nº aprox. de participantes | J5: Observação
B6: DH 1 | C6: 1 | D6: Sala 1 | E6: Ter/Qui | F6: 46259 | G6: 46289 | H6: 10 | I6: Período inclui feriado(s): 07/09
B7: DH 2 | C7: 1 | D7: Sala 2 | E7: Ter/Qui | F7: 46259 | G7: 46289 | H7: 10 | I7: Período inclui feriado(s): 07/09
B8: DH 3 | C8: 1 | D8: Sala 3 | E8: Ter/Qui | F8: 46259 | G8: 46289 | H8: 10 | I8: Período inclui feriado(s): 07/09
B9: DH 4 | C9: 2 | D9: Sala 1 | E9: Seg/Qua | F9: 46274 | G9: 46309 | H9: 10 | I9: Período inclui feriado(s): 12/10
B10: DH 5 | C10: 2 | D10: Sala 2 | E10: Seg/Qua | F10: 46274 | G10: 46309 | H10: 10 | I10: Período inclui feriado(s): 12/10
B11: DH 6 | C11: 2 | D11: Sala 3 | E11: Seg/Qua | F11: 46274 | G11: 46309 | H11: 10 | I11: Período inclui feriado(s): 12/10
B12: DH 7 | C12: 3 | D12: Sala 1 | E12: Ter/Qui | F12: 46294 | G12: 46324 | H12: 10 | I12: Período inclui feriado(s): 12/10
B13: DH 8 | C13: 3 | D13: Sala 2 | E13: Ter/Qui | F13: 46294 | G13: 46324 | H13: 10 | I13: Período inclui feriado(s): 12/10
B14: DH 9 | C14: 3 | D14: Sala 3 | E14: Ter/Qui | F14: 46294 | G14: 46324 | H14: 10 | I14: Período inclui feriado(s): 12/10
B15: DH 10 | C15: 4 | D15: Sala 1 | E15: Seg/Qua | F15: 46314 | G15: 46349 | H15: 10 | I15: Período inclui feriado(s): 02/11, 20/11
B16: DH 11 | C16: 4 | D16: Sala 2 | E16: Seg/Qua | F16: 46314 | G16: 46349 | H16: 10 | I16: Período inclui feriado(s): 02/11, 20/11
B17: DH 12 | C17: 4 | D17: Sala 3 | E17: Seg/Qua | F17: 46314 | G17: 46349 | H17: 10 | I17: Período inclui feriado(s): 02/11, 20/11
... B20: DH 15 | C20: 5 | D20: Sala 3 | E20: Ter/Qui | F20: 46329 | G20: 46359 | H20: 10 | I20: Período inclui feriado(s): 20/11
B22: Indicador | C22: Resultado | D22: Leitura
B23: Início da 1ª turma | C23: =MIN(F6:F20) | D23: Marco de início da fase de Desenvolvimento Humano
B24: Conclusão da 4ª turma | C24: =SMALL(G6:G20,4) | D24: Marco para liberar o primeiro lote de Curso Técnico (premissa: após 4 DH)
B25: Conclusão da 15ª turma (todas) | C25: =MAX(G6:G20) | D25: Fim estimado da fase de Desenvolvimento Humano
B26: Duração da fase DH (dias corridos) | C26: =C25-C23+1 | D26: Da 1ª turma iniciada até a 15ª concluída
B27: Capacidade simultânea máxima (turmas) | C27: 6 | D27: 3 sala(s) × interleaving por dia da semana (2 cadências/sala se 2x/semana)

Sheet 07_CENARIO_B
B2: CENÁRIO B — 3 SALAS | DH 5x/semana ★ CENÁRIO RECOMENDADO
B3: Maior velocidade; acompanha melhor a formacao das turmas. | Indicação: Recomendado para negociacao
B5: Turma DH | C5: Lote | D5: Sala | E5: Cadência | F5: Início | G5: Término | H5: Encontros | I5: Nº aprox. de participantes | J5: Observação
B6: DH 1 | C6: 1 | D6: Sala 1 | E6: Seg-Sex | F6: 46258 | G6: 46269 | H6: 10 | I6: —
B7: DH 2 | C7: 1 | D7: Sala 2 | E7: Seg-Sex | F7: 46258 | G7: 46269 | H7: 10 | I7: —
B8: DH 3 | C8: 1 | D8: Sala 3 | E8: Seg-Sex | F8: 46258 | G8: 46269 | H8: 10 | I8: —
B9: DH 4 | C9: 2 | D9: Sala 1 | E9: Seg-Sex | F9: 46273 | G9: 46286 | H9: 10 | I9: —
B10: DH 5 | C10: 2 | D10: Sala 2 | E10: Seg-Sex | F10: 46273 | G10: 46286 | H10: 10 | I10: —
B11: DH 6 | C11: 2 | D11: Sala 3 | E11: Seg-Sex | F11: 46273 | G11: 46286 | H11: 10 | I11: —
B12: DH 7 | C12: 3 | D12: Sala 1 | E12: Seg-Sex | F12: 46287 | G12: 46300 | H12: 10 | I12: —
B13: DH 8 | C13: 3 | D13: Sala 2 | E13: Seg-Sex | F13: 46287 | G13: 46300 | H13: 10 | I13: —
B14: DH 9 | C14: 3 | D14: Sala 3 | E14: Seg-Sex | F14: 46287 | G14: 46300 | H14: 10 | I14: —
B15: DH 10 | C15: 4 | D15: Sala 1 | E15: Seg-Sex | F15: 46301 | G15: 46315 | H15: 10 | I15: Período inclui feriado(s): 12/10
B16: DH 11 | C16: 4 | D16: Sala 2 | E16: Seg-Sex | F16: 46301 | G16: 46315 | H16: 10 | I16: Período inclui feriado(s): 12/10
B17: DH 12 | C17: 4 | D17: Sala 3 | E17: Seg-Sex | F17: 46301 | G17: 46315 | H17: 10 | I17: Período inclui feriado(s): 12/10
... B20: DH 15 | C20: 5 | D20: Sala 3 | E20: Seg-Sex | F20: 46316 | G20: 46330 | H20: 10 | I20: Período inclui feriado(s): 02/11
B22: Indicador | C22: Resultado | D22: Leitura
B23: Início da 1ª turma | C23: =MIN(F6:F20) | D23: Marco de início da fase de Desenvolvimento Humano
B24: Conclusão da 4ª turma | C24: =SMALL(G6:G20,4) | D24: Marco para liberar o primeiro lote de Curso Técnico (premissa: após 4 DH)
B25: Conclusão da 15ª turma (todas) | C25: =MAX(G6:G20) | D25: Fim estimado da fase de Desenvolvimento Humano
B26: Duração da fase DH (dias corridos) | C26: =C25-C23+1 | D26: Da 1ª turma iniciada até a 15ª concluída
B27: Capacidade simultânea máxima (turmas) | C27: 3 | D27: 3 sala(s) × interleaving por dia da semana (2 cadências/sala se 2x/semana)

Sheet 08_CENARIO_C
B2: CENÁRIO C — 2 SALAS | DH 2x/semana
B3: Baixa capacidade; atravessa o recesso e termina em fevereiro. | Indicação: Nao recomendado
B5: Turma DH | C5: Lote | D5: Sala | E5: Cadência | F5: Início | G5: Término | H5: Encontros | I5: Nº aprox. de participantes | J5: Observação
B6: DH 1 | C6: 1 | D6: Sala 1 | E6: Ter/Qui | F6: 46259 | G6: 46289 | H6: 10 | I6: Período inclui feriado(s): 07/09
B7: DH 2 | C7: 1 | D7: Sala 2 | E7: Ter/Qui | F7: 46259 | G7: 46289 | H7: 10 | I7: Período inclui feriado(s): 07/09
B8: DH 3 | C8: 1 | D8: Sala 1 | E8: Seg/Qua | F8: 46258 | G8: 46293 | H8: 10 | I8: Período inclui feriado(s): 07/09
B9: DH 4 | C9: 2 | D9: Sala 2 | E9: Seg/Qua | F9: 46274 | G9: 46309 | H9: 10 | I9: Período inclui feriado(s): 12/10
B10: DH 5 | C10: 2 | D10: Sala 1 | E10: Ter/Qui | F10: 46294 | G10: 46324 | H10: 10 | I10: Período inclui feriado(s): 12/10
B11: DH 6 | C11: 2 | D11: Sala 2 | E11: Ter/Qui | F11: 46294 | G11: 46324 | H11: 10 | I11: Período inclui feriado(s): 12/10
B12: DH 7 | C12: 3 | D12: Sala 1 | E12: Seg/Qua | F12: 46295 | G12: 46335 | H12: 10 | I12: Período inclui feriado(s): 12/10, 02/11
B13: DH 8 | C13: 3 | D13: Sala 2 | E13: Seg/Qua | F13: 46314 | G13: 46349 | H13: 10 | I13: Período inclui feriado(s): 02/11, 20/11
B14: DH 9 | C14: 3 | D14: Sala 1 | E14: Ter/Qui | F14: 46329 | G14: 46359 | H14: 10 | I14: Período inclui feriado(s): 20/11
B15: DH 10 | C15: 4 | D15: Sala 2 | E15: Ter/Qui | F15: 46329 | G15: 46359 | H15: 10 | I15: Período inclui feriado(s): 20/11
B16: DH 11 | C16: 4 | D16: Sala 1 | E16: Seg/Qua | F16: 46337 | G16: 46370 | H16: 10 | I16: Período inclui feriado(s): 20/11
B17: DH 12 | C17: 4 | D17: Sala 2 | E17: Seg/Qua | F17: 46351 | G17: 46405 | H17: 10 | I17: Atravessa o recesso institucional (21/12-08/01) — pendente de confirmação; Período inclui feriado(s): 25/12, 01/01
... B20: DH 15 | C20: 5 | D20: Sala 1 | E20: Seg/Qua | F20: 46372 | G20: 46426 | H20: 10 | I20: Atravessa o recesso institucional (21/12-08/01) — pendente de confirmação; Período inclui feriado(s): 25/12, 01/01
B22: Indicador | C22: Resultado | D22: Leitura
B23: Início da 1ª turma | C23: =MIN(F6:F20) | D23: Marco de início da fase de Desenvolvimento Humano
B24: Conclusão da 4ª turma | C24: =SMALL(G6:G20,4) | D24: Marco para liberar o primeiro lote de Curso Técnico (premissa: após 4 DH)
B25: Conclusão da 15ª turma (todas) | C25: =MAX(G6:G20) | D25: Fim estimado da fase de Desenvolvimento Humano
B26: Duração da fase DH (dias corridos) | C26: =C25-C23+1 | D26: Da 1ª turma iniciada até a 15ª concluída
B27: Capacidade simultânea máxima (turmas) | C27: 4 | D27: 2 sala(s) × interleaving por dia da semana (2 cadências/sala se 2x/semana)

Sheet 09_CENARIO_D
B2: CENÁRIO D — 2 SALAS | DH 5x/semana
B3: Viavel, porem com pouca folga e alta intensidade diaria. | Indicação: Plano de contingencia
B5: Turma DH | C5: Lote | D5: Sala | E5: Cadência | F5: Início | G5: Término | H5: Encontros | I5: Nº aprox. de participantes | J5: Observação
B6: DH 1 | C6: 1 | D6: Sala 1 | E6: Seg-Sex | F6: 46258 | G6: 46269 | H6: 10 | I6: —
B7: DH 2 | C7: 1 | D7: Sala 2 | E7: Seg-Sex | F7: 46258 | G7: 46269 | H7: 10 | I7: —
B8: DH 3 | C8: 2 | D8: Sala 1 | E8: Seg-Sex | F8: 46273 | G8: 46286 | H8: 10 | I8: —
B9: DH 4 | C9: 2 | D9: Sala 2 | E9: Seg-Sex | F9: 46273 | G9: 46286 | H9: 10 | I9: —
B10: DH 5 | C10: 3 | D10: Sala 1 | E10: Seg-Sex | F10: 46287 | G10: 46300 | H10: 10 | I10: —
B11: DH 6 | C11: 3 | D11: Sala 2 | E11: Seg-Sex | F11: 46287 | G11: 46300 | H11: 10 | I11: —
B12: DH 7 | C12: 4 | D12: Sala 1 | E12: Seg-Sex | F12: 46301 | G12: 46315 | H12: 10 | I12: Período inclui feriado(s): 12/10
B13: DH 8 | C13: 4 | D13: Sala 2 | E13: Seg-Sex | F13: 46301 | G13: 46315 | H13: 10 | I13: Período inclui feriado(s): 12/10
B14: DH 9 | C14: 5 | D14: Sala 1 | E14: Seg-Sex | F14: 46316 | G14: 46330 | H14: 10 | I14: Período inclui feriado(s): 02/11
B15: DH 10 | C15: 5 | D15: Sala 2 | E15: Seg-Sex | F15: 46316 | G15: 46330 | H15: 10 | I15: Período inclui feriado(s): 02/11
B16: DH 11 | C16: 6 | D16: Sala 1 | E16: Seg-Sex | F16: 46331 | G16: 46344 | H16: 10 | I16: —
B17: DH 12 | C17: 6 | D17: Sala 2 | E17: Seg-Sex | F17: 46331 | G17: 46344 | H17: 10 | I17: —
... B20: DH 15 | C20: 8 | D20: Sala 1 | E20: Seg-Sex | F20: 46360 | G20: 46373 | H20: 10 | I20: —
B22: Indicador | C22: Resultado | D22: Leitura
B23: Início da 1ª turma | C23: =MIN(F6:F20) | D23: Marco de início da fase de Desenvolvimento Humano
B24: Conclusão da 4ª turma | C24: =SMALL(G6:G20,4) | D24: Marco para liberar o primeiro lote de Curso Técnico (premissa: após 4 DH)
B25: Conclusão da 15ª turma (todas) | C25: =MAX(G6:G20) | D25: Fim estimado da fase de Desenvolvimento Humano
B26: Duração da fase DH (dias corridos) | C26: =C25-C23+1 | D26: Da 1ª turma iniciada até a 15ª concluída
B27: Capacidade simultânea máxima (turmas) | C27: 2 | D27: 2 sala(s) × interleaving por dia da semana (2 cadências/sala se 2x/semana)

Sheet 10_CRONOGRAMA_MESTRE
B2: CRONOGRAMA MESTRE DE PAULÍNIA — VISÃO COMPLETA DA EXECUÇÃO
B3: Cenário recomendado (B: 3 salas, DH 5x/semana) — do início da 1ª Palestra ao fim da Consultoria Individual
B5: Etapa | C5: Atividade / Turma | D5: Início | E5: Término | F5: Local / Sala | G5: Observação (premissa/situação)
B6: PS | C6: Palestras de Sensibilização (PS 01-30) | D6: 46245 | E6: 46310 | F6: A definir por comunidade | G6: 3x/semana (Ter/Qua/Qui), 2h cada — Confirmada
B7: DH | C7: DH 1 | D7: 46258 | E7: 46269 | F7: Sala 1 | G7: Cadência Seg-Sex — Cenário B (recomendado)
B8: DH | C8: DH 2 | D8: 46258 | E8: 46269 | F8: Sala 2 | G8: Cadência Seg-Sex — Cenário B (recomendado)
B9: DH | C9: DH 3 | D9: 46258 | E9: 46269 | F9: Sala 3 | G9: Cadência Seg-Sex — Cenário B (recomendado)
B10: REC | C10: Feriado: Independencia do Brasil | D10: 46272 | E10: 46272 | F10: — | G10: Confirmada (calendário municipal)
B11: DH | C11: DH 4 | D11: 46273 | E11: 46286 | F11: Sala 1 | G11: Cadência Seg-Sex — Cenário B (recomendado)
B12: DH | C12: DH 5 | D12: 46273 | E12: 46286 | F12: Sala 2 | G12: Cadência Seg-Sex — Cenário B (recomendado)
B13: DH | C13: DH 6 | D13: 46273 | E13: 46286 | F13: Sala 3 | G13: Cadência Seg-Sex — Cenário B (recomendado)
B14: OG | C14: OG 1 | D14: 46276 | E14: 46279 | F14: Espaço OG 1 (dedicado, fora das 3 salas de DH) | G14: Predecessora: DH 1 — Premissa provisória
B15: OG | C15: OG 2 | D15: 46276 | E15: 46279 | F15: Espaço OG 2 (dedicado, fora das 3 salas de DH) | G15: Predecessora: DH 2 — Premissa provisória
B16: OG | C16: OG 3 | D16: 46276 | E16: 46279 | F16: Espaço OG 3 (dedicado, fora das 3 salas de DH) | G16: Predecessora: DH 3 — Premissa provisória
B17: DH | C17: DH 7 | D17: 46287 | E17: 46300 | F17: Sala 1 | G17: Cadência Seg-Sex — Cenário B (recomendado)
... B55: CT | C55: CT4b — Preparacao de Alimentos | D55: 46405 | E55: 46422 | F55: Fundo Social / SENAC | G55: 56h, 14 encontros, noturno
B57: LEGENDA
C58: PS - Palestra de Sensibilização
C59: DH - Desenvolvimento Humano
C60: OG - Oficina de Gestão
C61: CT - Curso Técnico
C62: EAD - Curso Online
C63: CI - Consultoria Individual
C64: REC - Recesso / feriado

Sheet 11_AGENDA_POR_SALA
B2: AGENDA POR SALA — SEM SOBREPOSIÇÃO CONFIRMADA
B3: Cenário B (recomendado): 3 salas internas (DH + OG) — cursos técnicos ocorrem em fornecedores externos (ver tabela abaixo)
B5: SALAS INTERNAS — DESENVOLVIMENTO HUMANO E OFICINA DE GESTÃO
B6: Sala | C6: Turma | D6: Tipo | E6: Início | F6: Término | G6: Cadência | H6: Conflito de horário? | I6: Observação
B7: Espaço OG 1 (dedicado, fora das 3 salas de DH) | C7: OG 1 | D7: OG | E7: 46276 | F7: 46279 | G7: Seg-Sex (2 encontros) | H7: Não (verificado por dia da semana)
B8: Espaço OG 1 (dedicado, fora das 3 salas de DH) | C8: OG 4 | D8: OG | E8: 46293 | F8: 46294 | G8: Seg-Sex (2 encontros) | H8: Não (verificado por dia da semana)
B9: Espaço OG 1 (dedicado, fora das 3 salas de DH) | C9: OG 7 | D9: OG | E9: 46308 | F9: 46309 | G9: Seg-Sex (2 encontros) | H9: Não (verificado por dia da semana)
B10: Espaço OG 1 (dedicado, fora das 3 salas de DH) | C10: OG 10 | D10: OG | E10: 46322 | F10: 46323 | G10: Seg-Sex (2 encontros) | H10: Não (verificado por dia da semana)
B11: Espaço OG 1 (dedicado, fora das 3 salas de DH) | C11: OG 13 | D11: OG | E11: 46337 | F11: 46338 | G11: Seg-Sex (2 encontros) | H11: Não (verificado por dia da semana)
B12: Espaço OG 2 (dedicado, fora das 3 salas de DH) | C12: OG 2 | D12: OG | E12: 46276 | F12: 46279 | G12: Seg-Sex (2 encontros) | H12: Não (verificado por dia da semana)
B13: Espaço OG 2 (dedicado, fora das 3 salas de DH) | C13: OG 5 | D13: OG | E13: 46293 | F13: 46294 | G13: Seg-Sex (2 encontros) | H13: Não (verificado por dia da semana)
B14: Espaço OG 2 (dedicado, fora das 3 salas de DH) | C14: OG 8 | D14: OG | E14: 46308 | F14: 46309 | G14: Seg-Sex (2 encontros) | H14: Não (verificado por dia da semana)
B15: Espaço OG 2 (dedicado, fora das 3 salas de DH) | C15: OG 11 | D15: OG | E15: 46322 | F15: 46323 | G15: Seg-Sex (2 encontros) | H15: Não (verificado por dia da semana)
B16: Espaço OG 2 (dedicado, fora das 3 salas de DH) | C16: OG 14 | D16: OG | E16: 46337 | F16: 46338 | G16: Seg-Sex (2 encontros) | H16: Não (verificado por dia da semana)
B17: Espaço OG 3 (dedicado, fora das 3 salas de DH) | C17: OG 3 | D17: OG | E17: 46276 | F17: 46279 | G17: Seg-Sex (2 encontros) | H17: Não (verificado por dia da semana)
B18: Espaço OG 3 (dedicado, fora das 3 salas de DH) | C18: OG 6 | D18: OG | E18: 46293 | F18: 46294 | G18: Seg-Sex (2 encontros) | H18: Não (verificado por dia da semana)
... B36: Sala 3 | C36: DH 15 | D36: DH | E36: 46316 | F36: 46330 | G36: Seg-Sex | H36: Não (verificado por dia da semana)
B38: LOCAIS EXTERNOS — CURSOS TÉCNICOS (fornecedores)
B39: Fornecedor / Local | C39: Turma | D39: Tema | E39: Início | F39: Término | G39: Período livre até próxima turma | H39: Observação
B40: Fundo Social / SENAI | C40: CT1a | D40: Corte e Costura | E40: 46293 | F40: 46302 | G40: 6 dias até CT1b | H40: —
B41: Fundo Social / SENAI | C41: CT1b | D41: Corte e Costura | E41: 46308 | F41: 46317 | G41: Última turma desta trilha | H41: —
B42: Fundo Social / SENAC | C42: CT3 | D42: Beleza / Unhas | E42: 46321 | F42: 46335 | G42: 3 dias até CT5 | H42: —
B43: Fundo Social / SENAC | C43: CT5 | D43: Beleza / Cabelos Cacheados e Crespos | E43: 46338 | F43: 46358 | G43: 5 dias até CT4a | H43: —
B44: Fundo Social / SENAC | C44: CT4a | D44: Preparacao de Alimentos | E44: 46363 | F44: 46401 | G44: 4 dias até CT4b | H44: —
B45: Fundo Social / SENAC | C45: CT4b | D45: Preparacao de Alimentos | E45: 46405 | F45: 46422 | G45: Última turma desta trilha | H45: —
B46: SENAI Paulinia | C46: CT7a | D46: Eletrica | E46: 46293 | F46: 46321 | G46: 3 dias até CT7b | H46: —
B47: SENAI Paulinia | C47: CT7b | D47: Eletrica | E47: 46324 | F47: 46353 | G47: 3 dias até CT6 | H47: —
B48: SENAI Paulinia | C48: CT6 | D48: Automacao | E48: 46356 | F48: 46402 | G48: Última turma desta trilha | H48: —
B49: ? (fornecedor nao confirmado) | C49: CT2 | D49: Jardinagem | E49: 46293 | F49: 46304 | G49: Última turma desta trilha | H49: Fornecedor não confirmado

Sheet 12_TURMAS_DH
B2: VISÃO POR TURMA — PALESTRAS (PS) E DESENVOLVIMENTO HUMANO (DH)
B3: Cenário recomendado (B: 3 salas, DH 5x/semana) — ver abas 06-09 para os outros 3 cenários
B5: PALESTRAS DE SENSIBILIZAÇÃO (PS 01 – PS 30)
B6: Turma | C6: Data | D6: Dia da semana | E6: Carga horária | F6: Encontros | G6: Nº aprox. participantes | H6: Predecessora | I6: Situação da informação
B7: PS 01 | C7: 46245 | D7: Terça | E7: 2h | F7: 1 | G7: 20-40 | H7: — | I7: Premissa provisória
B8: PS 02 | C8: 46246 | D8: Quarta | E8: 2h | F8: 1 | G8: 20-40 | H8: — | I8: Premissa provisória
B9: PS 03 | C9: 46247 | D9: Quinta | E9: 2h | F9: 1 | G9: 20-40 | H9: — | I9: Premissa provisória
B10: PS 04 | C10: 46252 | D10: Terça | E10: 2h | F10: 1 | G10: 20-40 | H10: — | I10: Premissa provisória
B11: PS 05 | C11: 46253 | D11: Quarta | E11: 2h | F11: 1 | G11: 20-40 | H11: — | I11: Premissa provisória
B12: PS 06 | C12: 46254 | D12: Quinta | E12: 2h | F12: 1 | G12: 20-40 | H12: — | I12: Premissa provisória
B13: PS 07 | C13: 46259 | D13: Terça | E13: 2h | F13: 1 | G13: 20-40 | H13: — | I13: Premissa provisória
B14: PS 08 | C14: 46260 | D14: Quarta | E14: 2h | F14: 1 | G14: 20-40 | H14: — | I14: Premissa provisória
B15: PS 09 | C15: 46261 | D15: Quinta | E15: 2h | F15: 1 | G15: 20-40 | H15: — | I15: Premissa provisória
B16: PS 10 | C16: 46266 | D16: Terça | E16: 2h | F16: 1 | G16: 20-40 | H16: — | I16: Premissa provisória
B17: PS 11 | C17: 46267 | D17: Quarta | E17: 2h | F17: 1 | G17: 20-40 | H17: — | I17: Premissa provisória
B18: PS 12 | C18: 46268 | D18: Quinta | E18: 2h | F18: 1 | G18: 20-40 | H18: — | I18: Premissa provisória
... B36: PS 30 | C36: 46310 | D36: Quinta | E36: 2h | F36: 1 | G36: 20-40 | H36: — | I36: Premissa provisória
B38: DESENVOLVIMENTO HUMANO (DH 01 – DH 15) — Cenário B
B39: Turma | C39: Início | D39: Término | E39: Frequência | F39: Carga horária | G39: Encontros | H39: Sala | I39: Nº aprox. participantes | J39: Predecessora / Situação
B40: DH 1 | C40: 46258 | D40: 46269 | E40: Seg-Sex | F40: 20h (premissa; alternativa 22h) | G40: 10 | H40: Sala 1 | I40: 20-40 | J40: PS 01 e PS 02 (regra 2 PS = 1 DH — premissa)
B41: DH 2 | C41: 46258 | D41: 46269 | E41: Seg-Sex | F41: 20h (premissa; alternativa 22h) | G41: 10 | H41: Sala 2 | I41: 20-40 | J41: PS 03 e PS 04 (regra 2 PS = 1 DH — premissa)
B42: DH 3 | C42: 46258 | D42: 46269 | E42: Seg-Sex | F42: 20h (premissa; alternativa 22h) | G42: 10 | H42: Sala 3 | I42: 20-40 | J42: PS 05 e PS 06 (regra 2 PS = 1 DH — premissa)
B43: DH 4 | C43: 46273 | D43: 46286 | E43: Seg-Sex | F43: 20h (premissa; alternativa 22h) | G43: 10 | H43: Sala 1 | I43: 20-40 | J43: PS 07 e PS 08 (regra 2 PS = 1 DH — premissa)
B44: DH 5 | C44: 46273 | D44: 46286 | E44: Seg-Sex | F44: 20h (premissa; alternativa 22h) | G44: 10 | H44: Sala 2 | I44: 20-40 | J44: PS 09 e PS 10 (regra 2 PS = 1 DH — premissa)
B45: DH 6 | C45: 46273 | D45: 46286 | E45: Seg-Sex | F45: 20h (premissa; alternativa 22h) | G45: 10 | H45: Sala 3 | I45: 20-40 | J45: PS 11 e PS 12 (regra 2 PS = 1 DH — premissa)
B46: DH 7 | C46: 46287 | D46: 46300 | E46: Seg-Sex | F46: 20h (premissa; alternativa 22h) | G46: 10 | H46: Sala 1 | I46: 20-40 | J46: PS 13 e PS 14 (regra 2 PS = 1 DH — premissa)
B47: DH 8 | C47: 46287 | D47: 46300 | E47: Seg-Sex | F47: 20h (premissa; alternativa 22h) | G47: 10 | H47: Sala 2 | I47: 20-40 | J47: PS 15 e PS 16 (regra 2 PS = 1 DH — premissa)
B48: DH 9 | C48: 46287 | D48: 46300 | E48: Seg-Sex | F48: 20h (premissa; alternativa 22h) | G48: 10 | H48: Sala 3 | I48: 20-40 | J48: PS 17 e PS 18 (regra 2 PS = 1 DH — premissa)
B49: DH 10 | C49: 46301 | D49: 46315 | E49: Seg-Sex | F49: 20h (premissa; alternativa 22h) | G49: 10 | H49: Sala 1 | I49: 20-40 | J49: PS 19 e PS 20 (regra 2 PS = 1 DH — premissa)
B50: DH 11 | C50: 46301 | D50: 46315 | E50: Seg-Sex | F50: 20h (premissa; alternativa 22h) | G50: 10 | H50: Sala 2 | I50: 20-40 | J50: PS 21 e PS 22 (regra 2 PS = 1 DH — premissa)
B51: DH 12 | C51: 46301 | D51: 46315 | E51: Seg-Sex | F51: 20h (premissa; alternativa 22h) | G51: 10 | H51: Sala 3 | I51: 20-40 | J51: PS 23 e PS 24 (regra 2 PS = 1 DH — premissa)
... B54: DH 15 | C54: 46316 | D54: 46330 | E54: Seg-Sex | F54: 20h (premissa; alternativa 22h) | G54: 10 | H54: Sala 3 | I54: 20-40 | J54: PS 29 e PS 30 (regra 2 PS = 1 DH — premissa)

Sheet 13_OFICINAS_GESTAO
B2: OFICINA DE GESTÃO (OG) — DETALHAMENTO DE TURMAS
B3: Premissa provisória: 1 turma de OG por turma de DH concluída (15 no total). Ver divergência com a regra "2 DH = 1 OG + 1 CT" nas abas 01/02/03.
B5: Turma | C5: Início | D5: Término | E5: Carga horária | F5: Encontros | G5: Sala | H5: Nº aprox. participantes | I5: Predecessora | J5: Classificação
B6: OG 1 | C6: 46276 | D6: 46279 | E6: 4h | F6: 2 | G6: Espaço OG 1 (dedicado, fora das 3 salas de DH) | H6: 15-18 | I6: DH 1 concluída | J6: Premissa provisória
B7: OG 2 | C7: 46276 | D7: 46279 | E7: 4h | F7: 2 | G7: Espaço OG 2 (dedicado, fora das 3 salas de DH) | H7: 15-18 | I7: DH 2 concluída | J7: Premissa provisória
B8: OG 3 | C8: 46276 | D8: 46279 | E8: 4h | F8: 2 | G8: Espaço OG 3 (dedicado, fora das 3 salas de DH) | H8: 15-18 | I8: DH 3 concluída | J8: Premissa provisória
B9: OG 4 | C9: 46293 | D9: 46294 | E9: 4h | F9: 2 | G9: Espaço OG 1 (dedicado, fora das 3 salas de DH) | H9: 15-18 | I9: DH 4 concluída | J9: Premissa provisória
B10: OG 5 | C10: 46293 | D10: 46294 | E10: 4h | F10: 2 | G10: Espaço OG 2 (dedicado, fora das 3 salas de DH) | H10: 15-18 | I10: DH 5 concluída | J10: Premissa provisória
B11: OG 6 | C11: 46293 | D11: 46294 | E11: 4h | F11: 2 | G11: Espaço OG 3 (dedicado, fora das 3 salas de DH) | H11: 15-18 | I11: DH 6 concluída | J11: Premissa provisória
B12: OG 7 | C12: 46308 | D12: 46309 | E12: 4h | F12: 2 | G12: Espaço OG 1 (dedicado, fora das 3 salas de DH) | H12: 15-18 | I12: DH 7 concluída | J12: Premissa provisória
B13: OG 8 | C13: 46308 | D13: 46309 | E13: 4h | F13: 2 | G13: Espaço OG 2 (dedicado, fora das 3 salas de DH) | H13: 15-18 | I13: DH 8 concluída | J13: Premissa provisória
B14: OG 9 | C14: 46308 | D14: 46309 | E14: 4h | F14: 2 | G14: Espaço OG 3 (dedicado, fora das 3 salas de DH) | H14: 15-18 | I14: DH 9 concluída | J14: Premissa provisória
B15: OG 10 | C15: 46322 | D15: 46323 | E15: 4h | F15: 2 | G15: Espaço OG 1 (dedicado, fora das 3 salas de DH) | H15: 15-18 | I15: DH 10 concluída | J15: Premissa provisória
B16: OG 11 | C16: 46322 | D16: 46323 | E16: 4h | F16: 2 | G16: Espaço OG 2 (dedicado, fora das 3 salas de DH) | H16: 15-18 | I16: DH 11 concluída | J16: Premissa provisória
B17: OG 12 | C17: 46322 | D17: 46323 | E17: 4h | F17: 2 | G17: Espaço OG 3 (dedicado, fora das 3 salas de DH) | H17: 15-18 | I17: DH 12 concluída | J17: Premissa provisória
... B20: OG 15 | C20: 46337 | D20: 46338 | E20: 4h | F20: 2 | G20: Espaço OG 3 (dedicado, fora das 3 salas de DH) | H20: 15-18 | I20: DH 15 concluída | J20: Premissa provisória

Sheet 14_CURSOS_TECNICOS
B2: CURSOS TÉCNICOS (CT) — DETALHAMENTO DE TURMAS
B3: 10 turmas confirmadas na planilha operacional. Meta contratual do PDF macro é 13 — faltam 3 turmas a definir (ver aba 02).
B5: Sigla | C5: Tema | D5: Início | E5: Término | F5: Carga horária | G5: Encontros | H5: Mín. | I5: Máx. | J5: Fornecedor / Local | K5: Predecessora / Situação
B6: CT1a | C6: Corte e Costura | D6: 46293 | E6: 46302 | F6: 32h | G6: 8 | H6: 15 | I6: 18 | J6: Fundo Social / SENAI | K6: 4ª turma de DH concluída em 28/09/2026 (premissa: gatilho após 4 DH + 1 semana)
B7: CT1b | C7: Corte e Costura | D7: 46308 | E7: 46317 | F7: 32h | G7: 8 | H7: 15 | I7: 18 | J7: Fundo Social / SENAI | K7: 4ª turma de DH concluída em 28/09/2026 (premissa: gatilho após 4 DH + 1 semana)
B8: CT3 | C8: Beleza / Unhas | D8: 46321 | E8: 46335 | F8: 40h | G8: 10 | H8: 15 | I8: 18 | J8: Fundo Social / SENAC | K8: 4ª turma de DH concluída em 28/09/2026 (premissa: gatilho após 4 DH + 1 semana)
B9: CT5 | C9: Beleza / Cabelos Cacheados e Crespos | D9: 46338 | E9: 46358 | F9: 56h | G9: 14 | H9: 15 | I9: 18 | J9: Fundo Social / SENAC | K9: 4ª turma de DH concluída em 28/09/2026 (premissa: gatilho após 4 DH + 1 semana)
B10: CT4a | C10: Preparacao de Alimentos | D10: 46363 | E10: 46401 | F10: 56h | G10: 14 | H10: 15 | I10: 18 | J10: Fundo Social / SENAC | K10: 4ª turma de DH concluída em 28/09/2026 (premissa: gatilho após 4 DH + 1 semana)
B11: CT4b | C11: Preparacao de Alimentos | D11: 46405 | E11: 46422 | F11: 56h | G11: 14 | H11: 15 | I11: 18 | J11: Fundo Social / SENAC | K11: 4ª turma de DH concluída em 28/09/2026 (premissa: gatilho após 4 DH + 1 semana)
B12: CT7a | C12: Eletrica | D12: 46293 | E12: 46321 | F12: 80h | G12: 20 | H12: 14 | I12: 16 | J12: SENAI Paulinia | K12: 4ª turma de DH concluída em 28/09/2026 (premissa: gatilho após 4 DH + 1 semana)
B13: CT7b | C13: Eletrica | D13: 46324 | E13: 46353 | F13: 80h | G13: 20 | H13: 14 | I13: 16 | J13: SENAI Paulinia | K13: 4ª turma de DH concluída em 28/09/2026 (premissa: gatilho após 4 DH + 1 semana)
B14: CT6 | C14: Automacao | D14: 46356 | E14: 46402 | F14: 80h | G14: 20 | H14: 14 | I14: 16 | J14: SENAI Paulinia | K14: 4ª turma de DH concluída em 28/09/2026 (premissa: gatilho após 4 DH + 1 semana)
B15: CT2 | C15: Jardinagem | D15: 46293 | E15: 46304 | F15: 40h | G15: 10 | H15: 15 | I15: 18 | J15: ? (fornecedor nao confirmado) | K15: 4ª turma de DH concluída em 28/09/2026 (premissa: gatilho após 4 DH + 1 semana)
B17: PENDENTE DE VALIDAÇÃO: 3 turmas adicionais necessárias para atingir a meta contratual de 13 turmas do PDF macro (Núcleo 2). Temas e fornecedores não definidos neste material — recomenda-se priorizar cursos com maior demanda identificada no diagnóstico de participantes.

Sheet 15_EAD_CONSULTORIAS
B2: CURSO EAD E CONSULTORIA INDIVIDUAL (CI)
B3: Etapas finais da trilha — Curso Técnico é pré-requisito para Consultoria Individual (confirmado no PDF macro)
B5: Atividade | C5: Início | D5: Término | E5: Carga horária / Meta | F5: Observação
B6: Curso EAD — Planejamento, Marketing e Finanças | C6: 46303 | D6: 46308 | E6: 6h / 3 módulos | F6: Início estimado logo após a conclusão do primeiro Curso Técnico de cada trilha (autoinstrucional)
B7: Consultoria Individual (CI) | C7: 46309 | D7: 46452 | E7: 3 atendimentos/pessoa; meta 150 pessoas | F7: Rolling: inicia conforme cada aluno conclui seu Curso Técnico. Meta cruzada entre nota da planilha operacional (450 atend./3) e PDF macro (13 turmas = 150 pessoas).

Sheet 16_RISCOS_E_DECISOES
B2: RISCOS, DIVERGÊNCIAS E DECISÕES PENDENTES
B3: Quadro consolidado para acompanhamento com Instituto da Criança, Sebrae e Petrobras
B5: Risco / Divergência | C5: Documentos envolvidos | D5: Impacto no cronograma | E5: Decisão necessária | F5: Responsável pela validação | G5: Status | H5: Recomendação provisória
B6: Carga horária do DH indefinida (20h x 22h) | C6: Proposta (xlsx) + PDF macro vs. ata de reunião | D6: Muda a duração de cada uma das 15 turmas em até 1 semana, deslocando toda a cadeia OG→CT→EAD→CI. | E6: Confirmar por escrito a carga horária oficial do DH junto ao Sebrae. | F6: Coordenação / Sebrae | G6: Aberto | H6: Formalizar 20h por e-mail/ata assinada antes de comunicar datas à Petrobras.
B7: Quantidade de turmas de Curso Técnico indefinida (10 x 13) | C7: Proposta (xlsx) vs. PDF macro | D7: Se 13 for a meta válida, é preciso contratar 3 novos fornecedores/turmas, o que pode adicionar 4-8 semanas ao cronograma de CT. | E7: Definir se a meta de 13 será cumprida em Paulínia e, em caso positivo, quais temas/fornecedores fecham a diferença. | F7: Coordenação / Instituto da Criança | G7: Aberto | H7: Levar a divergência à reunião de alinhamento com o Sebrae antes de fechar contratos.
B8: Disponibilidade real de salas (2 x 3) não confirmada | C8: "Possibilidades de Cronograma" (3 salas) vs. briefing (2 ou 3) | D8: É a variável que mais impacta a duração da fase DH: 73 dias (cenário recomendado, 3 salas) até 169 dias (cenário C, 2 salas). | E8: Confirmar contratualmente a disponibilidade exclusiva de 3 salas à noite, de segunda a sexta. | F8: Coordenação local / Espaço físico | G8: Aberto | H8: Adotar o Cenário B como referência de negociação, mas manter D como contingência caso só 2 salas sejam viabilizadas.
B9: Regra de composição da Oficina de Gestão (15 x ~7-8 turmas) | C9: Proposta (xlsx), linha J5 vs. anotação A28 | D9: Dobra ou reduz pela metade a necessidade de salas/horários dedicados à OG. | E9: Confirmar se cada DH gera sua própria OG (1:1) ou se as OG são formadas a partir de pares de turmas de DH. | F9: Coordenação pedagógica | G9: Aberto | H9: Assumir 1:1 (15 turmas) como premissa de trabalho até confirmação, por ser a leitura mais conservadora em capacidade.
B10: Fornecedor de Jardinagem não definido | C10: "Possibilidades de Cronograma", célula R48 = "?" | D10: Turma de Jardinagem não pode ser comunicada aos participantes sem fornecedor e local confirmados. | E10: Selecionar e contratar fornecedor para o curso de Jardinagem. | F10: Coordenação de parcerias | G10: Aberto | H10: Priorizar a definição nas próximas 4 semanas, antes da 4ª turma de DH concluir (gatilho do 1º Curso Técnico).
B11: Recesso institucional não confirmado formalmente | C11: Simulação de cenários (premissa observada) | D11: Cenários que se estendem para dezembro/janeiro (C e D) podem precisar de ajuste fino de datas conforme o recesso real. | E11: Confirmar datas oficiais de recesso institucional 2026/2027. | F11: Administrativo / RH | G11: Aberto | H11: Manter 21/12/2026-08/01/2027 como premissa de planejamento; ajustar se o recesso oficial for diferente.
B12: Prazo apertado até o início das Palestras | C12: Contexto do projeto — data atual 21/07/2026, início das PS em 11/08/2026 | D12: Restam menos de 3 semanas até a primeira Palestra de Sensibilização; qualquer atraso na confirmação de salas/premissas comprime a mobilização. | E12: Validar premissas críticas (salas, carga horária do DH) com urgência. | F12: Coordenação geral do projeto | G12: Aberto — urgente | H12: Tratar as pendências desta aba como prioridade das próximas 2 semanas.
B13: Quórum mínimo dos cursos técnicos variável (14-18) vs. referência única de 16 citada em reunião | C13: Proposta (xlsx) vs. ata de reunião | D13: Se 16 for aplicado a todos os cursos, turmas com quórum planejado de 14-15 podem não abrir. | E13: Confirmar quórum mínimo por fornecedor/curso, não um valor único. | F13: Coordenação de parcerias | G13: Aberto | H13: Negociar quórum por curso com cada fornecedor antes de divulgar datas.
B14: ACHADO DESTA ANÁLISE: as 3 salas de DH ficam saturadas o tempo todo no cenário recomendado (B) | C14: Modelagem desta análise (nenhum dos 4 documentos originais havia cruzado a agenda de salas do DH com a da OG) | D14: No cenário B, cada uma das 3 salas de DH recebe 5 lotes consecutivos sem dia livre durante os 73 dias da fase — não há horário disponível na mesma sala para a Oficina de Gestão. | E14: Confirmar a existência de pelo menos 3 espaços adicionais (fora das salas de DH) para rodar a OG em paralelo, ou aceitar que a OG só comece após o fim de toda a fase DH (04/11). | F14: Coordenação local / Espaço físico | G14: Aberto — novo | H14: Reservar 3 espaços dedicados à OG (ex.: salas de reunião, auditório, espaço comunitário) distintos das 3 salas de DH, seguindo a mesma cadência de liberação dos lotes.

Sheet 17_GANTT_EXECUTIVO
B2: GANTT EXECUTIVO — TRILHA COMPLETA (CENÁRIO RECOMENDADO)
B3: Grade semanal — cada coluna representa a segunda-feira da semana correspondente
B5: Linha | C5: 46244 | D5: 46251 | E5: 46258 | F5: 46265 | G5: 46272 | H5: 46279 | I5: 46286 | J5: 46293 | K5: 46300 | L5: 46307 | M5: 46314 | N5: 46321 | O5: 46328 | P5: 46335 | Q5: 46342 | R5: 46349 | S5: 46356 | T5: 46363 | U5: 46370 | V5: 46377 | W5: 46384 | X5: 46391 | Y5: 46398 | Z5: 46405 | AA5: 46412 | AB5: 46419 | AC5: 46426 | AD5: 46433 | AE5: 46440 | AF5: 46447
B6: Palestras de Sensibilização
B7: Desenvolvimento Humano (agregado)
B8: DH 1 (Sala 1)
B9: DH 2 (Sala 2)
B10: DH 3 (Sala 3)
B11: DH 4 (Sala 1)
B12: DH 5 (Sala 2)
B13: DH 6 (Sala 3)
B14: DH 7 (Sala 1)
B15: DH 8 (Sala 2)
B16: DH 9 (Sala 3)
B17: DH 10 (Sala 1)
... B42: Feriado: Confraternizacao Universal
